{
  "version": 8,
  "blockIdVersion": 11,
  "anchorX": 0,
  "anchorY": 0,
  "anchorZ": 0,
  "blocks": [
    {
      "x": -23,
      "y": 16,
      "z": 21,
      "name": "Prototype_Rock_Concrete_Brick"
    },
    {
      "x": -23,
      "y": 17,
      "z": 23,
      "name": "Prototype_Rock_Concrete_Brick"
    },
    {
      "x": -23,
      "y": 17,
      "z": 26,
      "name": "Prototype_Rock_Concrete_Brick"
    },
    {
      "x": -23,
      "y": 16,
      "z": 29,
      "name": "Prototype_Rock_Concrete_Brick"
    },
    {
      "x": -22,
      "y": 3,
      "z": 16,
      "name": "Prototype_Rock_Concrete_Brick"
    },
    {
      "x": -22,
      "y": 16,
      "z": 16,
      "name": "Prototype_Rock_Concrete_Brick"
    },
    {
      "x": -22,
      "y": 3,
      "z": 17,
      "name": "Prototype_Rock_Concrete_Brick"
    },
    {
      "x": -22,
      "y": 4,
      "z": 17,
      "name": "Prototype_Rock_Concrete_Brick"
    },
    {
      "x": -22,
      "y": 16,
      "z": 17,
      "name": "Prototype_Rock_Concrete_Brick"
    },
    {
      "x": -22,
      "y": 17,
      "z": 17,
      "name": "Prototype_Rock_Concrete_Brick"
    },
    {
      "x": -22,
      "y": 3,
      "z": 18,
      "name": "Prototype_Rock_Concrete_Brick"
    },
    {
      "x": -22,
      "y": 4,
      "z": 18,
      "name": "Prototype_Rock_Concrete_Brick"
    },
    {
      "x": -22,
      "y": 16,
      "z": 18,
      "name": "Prototype_Rock_Concrete_Brick"
    },
    {
      "x": -22,
      "y": 3,
      "z": 19,
      "name": "Prototype_Rock_Concrete_Brick"
    },
    {
      "x": -22,
      "y": 4,
      "z": 19,
      "name": "Prototype_Rock_Concrete_Brick"
    },
    {
      "x": -22,
      "y": 15,
      "z": 19,
      "name": "Prototype_Rock_Concrete_Brick"
    },
    {
      "x": -22,
      "y": 16,
      "z": 19,
      "name": "Prototype_Rock_Concrete_Brick"
    },
    {
      "x": -22,
      "y": 2,
      "z": 20,
      "name": "Prototype_Rock_Concrete_Brick"
    },
    {
      "x": -22,
      "y": 3,
      "z": 20,
      "name": "Prototype_Rock_Concrete_Brick"
    },
    {
      "x": -22,
      "y": 4,
      "z": 20,
      "name": "Prototype_Rock_Concrete_Brick"
    },
    {
      "x": -22,
      "y": 15,
      "z": 20,
      "name": "Prototype_Rock_Concrete_Brick"
    },
    {
      "x": -22,
      "y": 16,
      "z": 20,
      "name": "Prototype_Rock_Concrete_Brick"
    },
    {
      "x": -22,
      "y": 17,
      "z": 20,
      "name": "Prototype_Rock_Concrete_Brick"
    },
    {
      "x": -22,
      "y": 3,
      "z": 21,
      "name": "Prototype_Rock_Concrete_Brick"
    },
    {
      "x": -22,
      "y": 4,
      "z": 21,
      "name": "Prototype_Rock_Concrete_Brick"
    },
    {
      "x": -22,
      "y": 15,
      "z": 21,
      "name": "Prototype_Rock_Concrete_Brick"
    },
    {
      "x": -22,
      "y": 16,
      "z": 21,
      "name": "Prototype_Rock_Concrete_Brick"
    },
    {
      "x": -22,
      "y": 17,
      "z": 21,
      "name": "Prototype_Rock_Concrete_Brick"
    },
    {
      "x": -22,
      "y": 3,
      "z": 22,
      "name": "Prototype_Rock_Concrete_Brick"
    },
    {
      "x": -22,
      "y": 4,
      "z": 22,
      "name": "Prototype_Rock_Concrete_Brick"
    },
    {
      "x": -22,
      "y": 15,
      "z": 22,
      "name": "Prototype_Rock_Concrete_Brick"
    },
    {
      "x": -22,
      "y": 16,
      "z": 22,
      "name": "Prototype_Rock_Concrete_Brick"
    },
    {
      "x": -22,
      "y": 17,
      "z": 22,
      "name": "Prototype_Rock_Concrete_Brick"
    },
    {
      "x": -22,
      "y": 3,
      "z": 23,
      "name": "Prototype_Rock_Concrete_Brick"
    },
    {
      "x": -22,
      "y": 4,
      "z": 23,
      "name": "Prototype_Rock_Concrete_Brick"
    },
    {
      "x": -22,
      "y": 15,
      "z": 23,
      "name": "Prototype_Rock_Concrete_Brick"
    },
    {
      "x": -22,
      "y": 16,
      "z": 23,
      "name": "Prototype_Rock_Concrete_Brick"
    },
    {
      "x": -22,
      "y": 17,
      "z": 23,
      "name": "Prototype_Rock_Concrete_Brick"
    },
    {
      "x": -22,
      "y": 2,
      "z": 24,
      "name": "Prototype_Rock_Concrete_Brick"
    },
    {
      "x": -22,
      "y": 3,
      "z": 24,
      "name": "Prototype_Rock_Concrete_Brick"
    },
    {
      "x": -22,
      "y": 4,
      "z": 24,
      "name": "Prototype_Rock_Concrete_Brick"
    },
    {
      "x": -22,
      "y": 15,
      "z": 24,
      "name": "Prototype_Rock_Concrete_Brick"
    },
    {
      "x": -22,
      "y": 16,
      "z": 24,
      "name": "Prototype_Rock_Concrete_Brick"
    },
    {
      "x": -22,
      "y": 17,
      "z": 24,
      "name": "Prototype_Rock_Concrete_Brick"
    },
    {
      "x": -22,
      "y": 2,
      "z": 25,
      "name": "Prototype_Rock_Concrete_Brick"
    },
    {
      "x": -22,
      "y": 3,
      "z": 25,
      "name": "Prototype_Rock_Concrete_Brick"
    },
    {
      "x": -22,
      "y": 4,
      "z": 25,
      "name": "Prototype_Rock_Concrete_Brick"
    },
    {
      "x": -22,
      "y": 15,
      "z": 25,
      "name": "Prototype_Rock_Concrete_Brick"
    },
    {
      "x": -22,
      "y": 16,
      "z": 25,
      "name": "Prototype_Rock_Concrete_Brick"
    },
    {
      "x": -22,
      "y": 17,
      "z": 25,
      "name": "Prototype_Rock_Concrete_Brick"
    },
    {
      "x": -22,
      "y": 2,
      "z": 26,
      "name": "Prototype_Rock_Concrete_Brick"
    },
    {
      "x": -22,
      "y": 3,
      "z": 26,
      "name": "Prototype_Rock_Concrete_Brick"
    },
    {
      "x": -22,
      "y": 4,
      "z": 26,
      "name": "Prototype_Rock_Concrete_Brick"
    },
    {
      "x": -22,
      "y": 15,
      "z": 26,
      "name": "Prototype_Rock_Concrete_Brick"
    },
    {
      "x": -22,
      "y": 16,
      "z": 26,
      "name": "Prototype_Rock_Concrete_Brick"
    },
    {
      "x": -22,
      "y": 17,
      "z": 26,
      "name": "Prototype_Rock_Concrete_Brick"
    },
    {
      "x": -22,
      "y": 2,
      "z": 27,
      "name": "Prototype_Rock_Concrete_Brick"
    },
    {
      "x": -22,
      "y": 3,
      "z": 27,
      "name": "Prototype_Rock_Concrete_Brick"
    },
    {
      "x": -22,
      "y": 4,
      "z": 27,
      "name": "Prototype_Rock_Concrete_Brick"
    },
    {
      "x": -22,
      "y": 16,
      "z": 27,
      "name": "Prototype_Rock_Concrete_Brick"
    },
    {
      "x": -22,
      "y": 17,
      "z": 27,
      "name": "Prototype_Rock_Concrete_Brick"
    },
    {
      "x": -22,
      "y": 2,
      "z": 28,
      "name": "Prototype_Rock_Concrete_Brick"
    },
    {
      "x": -22,
      "y": 3,
      "z": 28,
      "name": "Prototype_Rock_Concrete_Brick"
    },
    {
      "x": -22,
      "y": 4,
      "z": 28,
      "name": "Prototype_Rock_Concrete_Brick"
    },
    {
      "x": -22,
      "y": 16,
      "z": 28,
      "name": "Prototype_Rock_Concrete_Brick"
    },
    {
      "x": -22,
      "y": 17,
      "z": 28,
      "name": "Prototype_Rock_Concrete_Brick"
    },
    {
      "x": -22,
      "y": 3,
      "z": 29,
      "name": "Prototype_Rock_Concrete_Brick"
    },
    {
      "x": -22,
      "y": 16,
      "z": 29,
      "name": "Prototype_Rock_Concrete_Brick"
    },
    {
      "x": -22,
      "y": 17,
      "z": 29,
      "name": "Prototype_Rock_Concrete_Brick"
    },
    {
      "x": -21,
      "y": 4,
      "z": 12,
      "name": "Prototype_Rock_Concrete_Brick"
    },
    {
      "x": -21,
      "y": 15,
      "z": 12,
      "name": "Prototype_Rock_Concrete_Brick"
    },
    {
      "x": -21,
      "y": 16,
      "z": 12,
      "name": "Prototype_Rock_Concrete_Brick"
    },
    {
      "x": -21,
      "y": 3,
      "z": 13,
      "name": "Prototype_Rock_Concrete_Brick"
    },
    {
      "x": -21,
      "y": 4,
      "z": 13,
      "name": "Prototype_Rock_Concrete_Brick"
    },
    {
      "x": -21,
      "y": 15,
      "z": 13,
      "name": "Prototype_Rock_Concrete_Brick"
    },
    {
      "x": -21,
      "y": 16,
      "z": 13,
      "name": "Prototype_Rock_Concrete_Brick"
    },
    {
      "x": -21,
      "y": 3,
      "z": 14,
      "name": "Prototype_Rock_Concrete_Brick"
    },
    {
      "x": -21,
      "y": 4,
      "z": 14,
      "name": "Prototype_Rock_Concrete_Brick"
    },
    {
      "x": -21,
      "y": 15,
      "z": 14,
      "name": "Prototype_Rock_Concrete_Brick"
    },
    {
      "x": -21,
      "y": 16,
      "z": 14,
      "name": "Prototype_Rock_Concrete_Brick"
    },
    {
      "x": -21,
      "y": 3,
      "z": 15,
      "name": "Prototype_Rock_Concrete_Brick"
    },
    {
      "x": -21,
      "y": 4,
      "z": 15,
      "name": "Prototype_Rock_Concrete_Brick"
    },
    {
      "x": -21,
      "y": 15,
      "z": 15,
      "name": "Prototype_Rock_Concrete_Brick"
    },
    {
      "x": -21,
      "y": 16,
      "z": 15,
      "name": "Prototype_Rock_Concrete_Brick"
    },
    {
      "x": -21,
      "y": 17,
      "z": 15,
      "name": "Prototype_Rock_Concrete_Brick"
    },
    {
      "x": -21,
      "y": 3,
      "z": 16,
      "name": "Prototype_Rock_Concrete_Brick"
    },
    {
      "x": -21,
      "y": 4,
      "z": 16,
      "name": "Prototype_Rock_Concrete_Brick"
    },
    {
      "x": -21,
      "y": 15,
      "z": 16,
      "name": "Prototype_Rock_Concrete_Brick"
    },
    {
      "x": -21,
      "y": 16,
      "z": 16,
      "name": "Prototype_Rock_Concrete_Brick"
    },
    {
      "x": -21,
      "y": 17,
      "z": 16,
      "name": "Prototype_Rock_Concrete_Brick"
    },
    {
      "x": -21,
      "y": 3,
      "z": 17,
      "name": "Prototype_Rock_Concrete_Brick"
    },
    {
      "x": -21,
      "y": 4,
      "z": 17,
      "name": "Prototype_Rock_Concrete_Brick"
    },
    {
      "x": -21,
      "y": 15,
      "z": 17,
      "name": "Prototype_Rock_Concrete_Brick"
    },
    {
      "x": -21,
      "y": 16,
      "z": 17,
      "name": "Prototype_Rock_Concrete_Brick"
    },
    {
      "x": -21,
      "y": 17,
      "z": 17,
      "name": "Prototype_Rock_Concrete_Brick"
    },
    {
      "x": -21,
      "y": 2,
      "z": 18,
      "name": "Prototype_Rock_Concrete_Brick"
    },
    {
      "x": -21,
      "y": 3,
      "z": 18,
      "name": "Prototype_Rock_Concrete_Brick"
    },
    {
      "x": -21,
      "y": 4,
      "z": 18,
      "name": "Prototype_Rock_Concrete_Brick"
    },
    {
      "x": -21,
      "y": 15,
      "z": 18,
      "name": "Prototype_Rock_Concrete_Brick"
    },
    {
      "x": -21,
      "y": 16,
      "z": 18,
      "name": "Prototype_Rock_Concrete_Brick"
    },
    {
      "x": -21,
      "y": 17,
      "z": 18,
      "name": "Prototype_Rock_Concrete_Brick"
    },
    {
      "x": -21,
      "y": 2,
      "z": 19,
      "name": "Prototype_Rock_Concrete_Brick"
    },
    {
      "x": -21,
      "y": 3,
      "z": 19,
      "name": "Prototype_Rock_Concrete_Brick"
    },
    {
      "x": -21,
      "y": 4,
      "z": 19,
      "name": "Prototype_Rock_Concrete_Brick"
    },
    {
      "x": -21,
      "y": 15,
      "z": 19,
      "name": "Prototype_Rock_Concrete_Brick"
    },
    {
      "x": -21,
      "y": 16,
      "z": 19,
      "name": "Prototype_Rock_Concrete_Brick"
    },
    {
      "x": -21,
      "y": 17,
      "z": 19,
      "name": "Prototype_Rock_Concrete_Brick"
    },
    {
      "x": -21,
      "y": 2,
      "z": 20,
      "name": "Prototype_Rock_Concrete_Brick"
    },
    {
      "x": -21,
      "y": 3,
      "z": 20,
      "name": "Prototype_Rock_Concrete_Brick"
    },
    {
      "x": -21,
      "y": 4,
      "z": 20,
      "name": "Prototype_Rock_Concrete_Brick"
    },
    {
      "x": -21,
      "y": 15,
      "z": 20,
      "name": "Prototype_Rock_Concrete_Brick"
    },
    {
      "x": -21,
      "y": 16,
      "z": 20,
      "name": "Prototype_Rock_Concrete_Brick"
    },
    {
      "x": -21,
      "y": 17,
      "z": 20,
      "name": "Prototype_Rock_Concrete_Brick"
    },
    {
      "x": -21,
      "y": 2,
      "z": 21,
      "name": "Prototype_Rock_Concrete_Brick"
    },
    {
      "x": -21,
      "y": 3,
      "z": 21,
      "name": "Prototype_Rock_Concrete_Brick"
    },
    {
      "x": -21,
      "y": 4,
      "z": 21,
      "name": "Prototype_Rock_Concrete_Brick"
    },
    {
      "x": -21,
      "y": 15,
      "z": 21,
      "name": "Prototype_Rock_Concrete_Brick"
    },
    {
      "x": -21,
      "y": 16,
      "z": 21,
      "name": "Prototype_Rock_Concrete_Brick"
    },
    {
      "x": -21,
      "y": 17,
      "z": 21,
      "name": "Prototype_Rock_Concrete_Brick"
    },
    {
      "x": -21,
      "y": 2,
      "z": 22,
      "name": "Prototype_Rock_Concrete_Brick"
    },
    {
      "x": -21,
      "y": 3,
      "z": 22,
      "name": "Prototype_Rock_Concrete_Brick"
    },
    {
      "x": -21,
      "y": 4,
      "z": 22,
      "name": "Prototype_Rock_Concrete_Brick"
    },
    {
      "x": -21,
      "y": 15,
      "z": 22,
      "name": "Prototype_Rock_Concrete_Brick"
    },
    {
      "x": -21,
      "y": 16,
      "z": 22,
      "name": "Prototype_Rock_Concrete_Brick"
    },
    {
      "x": -21,
      "y": 17,
      "z": 22,
      "name": "Prototype_Rock_Concrete_Brick"
    },
    {
      "x": -21,
      "y": 2,
      "z": 23,
      "name": "Prototype_Rock_Concrete_Brick"
    },
    {
      "x": -21,
      "y": 3,
      "z": 23,
      "name": "Prototype_Rock_Concrete_Brick"
    },
    {
      "x": -21,
      "y": 4,
      "z": 23,
      "name": "Prototype_Rock_Concrete_Brick"
    },
    {
      "x": -21,
      "y": 15,
      "z": 23,
      "name": "Prototype_Rock_Concrete_Brick"
    },
    {
      "x": -21,
      "y": 16,
      "z": 23,
      "name": "Prototype_Rock_Concrete_Brick"
    },
    {
      "x": -21,
      "y": 17,
      "z": 23,
      "name": "Prototype_Rock_Concrete_Brick"
    },
    {
      "x": -21,
      "y": 2,
      "z": 24,
      "name": "Prototype_Rock_Concrete_Brick"
    },
    {
      "x": -21,
      "y": 3,
      "z": 24,
      "name": "Prototype_Rock_Concrete_Brick"
    },
    {
      "x": -21,
      "y": 4,
      "z": 24,
      "name": "Prototype_Rock_Concrete_Brick"
    },
    {
      "x": -21,
      "y": 15,
      "z": 24,
      "name": "Prototype_Rock_Concrete_Brick"
    },
    {
      "x": -21,
      "y": 16,
      "z": 24,
      "name": "Prototype_Rock_Concrete_Brick"
    },
    {
      "x": -21,
      "y": 17,
      "z": 24,
      "name": "Prototype_Rock_Concrete_Brick"
    },
    {
      "x": -21,
      "y": 2,
      "z": 25,
      "name": "Prototype_Rock_Concrete_Brick"
    },
    {
      "x": -21,
      "y": 3,
      "z": 25,
      "name": "Prototype_Rock_Concrete_Brick"
    },
    {
      "x": -21,
      "y": 4,
      "z": 25,
      "name": "Prototype_Rock_Concrete_Brick"
    },
    {
      "x": -21,
      "y": 15,
      "z": 25,
      "name": "Prototype_Rock_Concrete_Brick"
    },
    {
      "x": -21,
      "y": 16,
      "z": 25,
      "name": "Prototype_Rock_Concrete_Brick"
    },
    {
      "x": -21,
      "y": 17,
      "z": 25,
      "name": "Prototype_Rock_Concrete_Brick"
    },
    {
      "x": -21,
      "y": 2,
      "z": 26,
      "name": "Prototype_Rock_Concrete_Brick"
    },
    {
      "x": -21,
      "y": 3,
      "z": 26,
      "name": "Prototype_Rock_Concrete_Brick"
    },
    {
      "x": -21,
      "y": 4,
      "z": 26,
      "name": "Prototype_Rock_Concrete_Brick"
    },
    {
      "x": -21,
      "y": 15,
      "z": 26,
      "name": "Prototype_Rock_Concrete_Brick"
    },
    {
      "x": -21,
      "y": 16,
      "z": 26,
      "name": "Prototype_Rock_Concrete_Brick"
    },
    {
      "x": -21,
      "y": 17,
      "z": 26,
      "name": "Prototype_Rock_Concrete_Brick"
    },
    {
      "x": -21,
      "y": 3,
      "z": 27,
      "name": "Prototype_Rock_Concrete_Brick"
    },
    {
      "x": -21,
      "y": 4,
      "z": 27,
      "name": "Prototype_Rock_Concrete_Brick"
    },
    {
      "x": -21,
      "y": 16,
      "z": 27,
      "name": "Prototype_Rock_Concrete_Brick"
    },
    {
      "x": -21,
      "y": 17,
      "z": 27,
      "name": "Prototype_Rock_Concrete_Brick"
    },
    {
      "x": -21,
      "y": 3,
      "z": 28,
      "name": "Prototype_Rock_Concrete_Brick"
    },
    {
      "x": -21,
      "y": 16,
      "z": 28,
      "name": "Prototype_Rock_Concrete_Brick"
    },
    {
      "x": -21,
      "y": 17,
      "z": 28,
      "name": "Prototype_Rock_Concrete_Brick"
    },
    {
      "x": -21,
      "y": 3,
      "z": 29,
      "name": "Prototype_Rock_Concrete_Brick"
    },
    {
      "x": -21,
      "y": 16,
      "z": 29,
      "name": "Prototype_Rock_Concrete_Brick"
    },
    {
      "x": -20,
      "y": 4,
      "z": 9,
      "name": "Prototype_Rock_Concrete_Brick"
    },
    {
      "x": -20,
      "y": 5,
      "z": 9,
      "name": "Prototype_Rock_Concrete_Brick"
    },
    {
      "x": -20,
      "y": 15,
      "z": 9,
      "name": "Prototype_Rock_Concrete_Brick"
    },
    {
      "x": -20,
      "y": 4,
      "z": 10,
      "name": "Prototype_Rock_Concrete_Brick"
    },
    {
      "x": -20,
      "y": 5,
      "z": 10,
      "name": "Prototype_Rock_Concrete_Brick"
    },
    {
      "x": -20,
      "y": 15,
      "z": 10,
      "name": "Prototype_Rock_Concrete_Brick"
    },
    {
      "x": -20,
      "y": 16,
      "z": 10,
      "name": "Prototype_Rock_Concrete_Brick"
    },
    {
      "x": -20,
      "y": 3,
      "z": 11,
      "name": "Prototype_Rock_Concrete_Brick"
    },
    {
      "x": -20,
      "y": 4,
      "z": 11,
      "name": "Prototype_Rock_Concrete_Brick"
    },
    {
      "x": -20,
      "y": 5,
      "z": 11,
      "name": "Prototype_Rock_Concrete_Brick"
    },
    {
      "x": -20,
      "y": 14,
      "z": 11,
      "name": "Prototype_Rock_Concrete_Brick"
    },
    {
      "x": -20,
      "y": 15,
      "z": 11,
      "name": "Prototype_Rock_Concrete_Brick"
    },
    {
      "x": -20,
      "y": 16,
      "z": 11,
      "name": "Prototype_Rock_Concrete_Brick"
    },
    {
      "x": -20,
      "y": 3,
      "z": 12,
      "name": "Prototype_Rock_Concrete_Brick"
    },
    {
      "x": -20,
      "y": 4,
      "z": 12,
      "name": "Prototype_Rock_Concrete_Brick"
    },
    {
      "x": -20,
      "y": 5,
      "z": 12,
      "name": "Prototype_Rock_Concrete_Brick"
    },
    {
      "x": -20,
      "y": 14,
      "z": 12,
      "name": "Prototype_Rock_Concrete_Brick"
    },
    {
      "x": -20,
      "y": 15,
      "z": 12,
      "name": "Prototype_Rock_Concrete_Brick"
    },
    {
      "x": -20,
      "y": 16,
      "z": 12,
      "name": "Prototype_Rock_Concrete_Brick"
    },
    {
      "x": -20,
      "y": 3,
      "z": 13,
      "name": "Prototype_Rock_Concrete_Brick"
    },
    {
      "x": -20,
      "y": 4,
      "z": 13,
      "name": "Prototype_Rock_Concrete_Brick"
    },
    {
      "x": -20,
      "y": 5,
      "z": 13,
      "name": "Prototype_Rock_Concrete_Brick"
    },
    {
      "x": -20,
      "y": 14,
      "z": 13,
      "name": "Prototype_Rock_Concrete_Brick"
    },
    {
      "x": -20,
      "y": 15,
      "z": 13,
      "name": "Prototype_Rock_Concrete_Brick"
    },
    {
      "x": -20,
      "y": 16,
      "z": 13,
      "name": "Prototype_Rock_Concrete_Brick"
    },
    {
      "x": -20,
      "y": 3,
      "z": 14,
      "name": "Prototype_Rock_Concrete_Brick"
    },
    {
      "x": -20,
      "y": 4,
      "z": 14,
      "name": "Prototype_Rock_Concrete_Brick"
    },
    {
      "x": -20,
      "y": 5,
      "z": 14,
      "name": "Prototype_Rock_Concrete_Brick"
    },
    {
      "x": -20,
      "y": 14,
      "z": 14,
      "name": "Prototype_Rock_Concrete_Brick"
    },
    {
      "x": -20,
      "y": 15,
      "z": 14,
      "name": "Prototype_Rock_Concrete_Brick"
    },
    {
      "x": -20,
      "y": 16,
      "z": 14,
      "name": "Prototype_Rock_Concrete_Brick"
    },
    {
      "x": -20,
      "y": 3,
      "z": 15,
      "name": "Prototype_Rock_Concrete_Brick"
    },
    {
      "x": -20,
      "y": 4,
      "z": 15,
      "name": "Prototype_Rock_Concrete_Brick"
    },
    {
      "x": -20,
      "y": 5,
      "z": 15,
      "name": "Prototype_Rock_Concrete_Brick"
    },
    {
      "x": -20,
      "y": 14,
      "z": 15,
      "name": "Prototype_Rock_Concrete_Brick"
    },
    {
      "x": -20,
      "y": 15,
      "z": 15,
      "name": "Prototype_Rock_Concrete_Brick"
    },
    {
      "x": -20,
      "y": 16,
      "z": 15,
      "name": "Prototype_Rock_Concrete_Brick"
    },
    {
      "x": -20,
      "y": 3,
      "z": 16,
      "name": "Prototype_Rock_Concrete_Brick"
    },
    {
      "x": -20,
      "y": 4,
      "z": 16,
      "name": "Prototype_Rock_Concrete_Brick"
    },
    {
      "x": -20,
      "y": 5,
      "z": 16,
      "name": "Prototype_Rock_Concrete_Brick"
    },
    {
      "x": -20,
      "y": 14,
      "z": 16,
      "name": "Prototype_Rock_Concrete_Brick"
    },
    {
      "x": -20,
      "y": 15,
      "z": 16,
      "name": "Prototype_Rock_Concrete_Brick"
    },
    {
      "x": -20,
      "y": 16,
      "z": 16,
      "name": "Prototype_Rock_Concrete_Brick"
    },
    {
      "x": -20,
      "y": 3,
      "z": 17,
      "name": "Prototype_Rock_Concrete_Brick"
    },
    {
      "x": -20,
      "y": 4,
      "z": 17,
      "name": "Prototype_Rock_Concrete_Brick"
    },
    {
      "x": -20,
      "y": 5,
      "z": 17,
      "name": "Prototype_Rock_Concrete_Brick"
    },
    {
      "x": -20,
      "y": 14,
      "z": 17,
      "name": "Prototype_Rock_Concrete_Brick"
    },
    {
      "x": -20,
      "y": 15,
      "z": 17,
      "name": "Prototype_Rock_Concrete_Brick"
    },
    {
      "x": -20,
      "y": 16,
      "z": 17,
      "name": "Prototype_Rock_Concrete_Brick"
    },
    {
      "x": -20,
      "y": 3,
      "z": 18,
      "name": "Prototype_Rock_Concrete_Brick"
    },
    {
      "x": -20,
      "y": 4,
      "z": 18,
      "name": "Prototype_Rock_Concrete_Brick"
    },
    {
      "x": -20,
      "y": 5,
      "z": 18,
      "name": "Prototype_Rock_Concrete_Brick"
    },
    {
      "x": -20,
      "y": 14,
      "z": 18,
      "name": "Prototype_Rock_Concrete_Brick"
    },
    {
      "x": -20,
      "y": 15,
      "z": 18,
      "name": "Prototype_Rock_Concrete_Brick"
    },
    {
      "x": -20,
      "y": 16,
      "z": 18,
      "name": "Prototype_Rock_Concrete_Brick"
    },
    {
      "x": -20,
      "y": 3,
      "z": 19,
      "name": "Prototype_Rock_Concrete_Brick"
    },
    {
      "x": -20,
      "y": 4,
      "z": 19,
      "name": "Prototype_Rock_Concrete_Brick"
    },
    {
      "x": -20,
      "y": 5,
      "z": 19,
      "name": "Prototype_Rock_Concrete_Brick"
    },
    {
      "x": -20,
      "y": 14,
      "z": 19,
      "name": "Prototype_Rock_Concrete_Brick"
    },
    {
      "x": -20,
      "y": 15,
      "z": 19,
      "name": "Prototype_Rock_Concrete_Brick"
    },
    {
      "x": -20,
      "y": 16,
      "z": 19,
      "name": "Prototype_Rock_Concrete_Brick"
    },
    {
      "x": -20,
      "y": 3,
      "z": 20,
      "name": "Prototype_Rock_Concrete_Brick"
    },
    {
      "x": -20,
      "y": 4,
      "z": 20,
      "name": "Prototype_Rock_Concrete_Brick"
    },
    {
      "x": -20,
      "y": 5,
      "z": 20,
      "name": "Prototype_Rock_Concrete_Brick"
    },
    {
      "x": -20,
      "y": 15,
      "z": 20,
      "name": "Prototype_Rock_Concrete_Brick"
    },
    {
      "x": -20,
      "y": 16,
      "z": 20,
      "name": "Prototype_Rock_Concrete_Brick"
    },
    {
      "x": -20,
      "y": 3,
      "z": 21,
      "name": "Prototype_Rock_Concrete_Brick"
    },
    {
      "x": -20,
      "y": 4,
      "z": 21,
      "name": "Prototype_Rock_Concrete_Brick"
    },
    {
      "x": -20,
      "y": 5,
      "z": 21,
      "name": "Prototype_Rock_Concrete_Brick"
    },
    {
      "x": -20,
      "y": 15,
      "z": 21,
      "name": "Prototype_Rock_Concrete_Brick"
    },
    {
      "x": -20,
      "y": 16,
      "z": 21,
      "name": "Prototype_Rock_Concrete_Brick"
    },
    {
      "x": -20,
      "y": 3,
      "z": 22,
      "name": "Prototype_Rock_Concrete_Brick"
    },
    {
      "x": -20,
      "y": 4,
      "z": 22,
      "name": "Prototype_Rock_Concrete_Brick"
    },
    {
      "x": -20,
      "y": 15,
      "z": 22,
      "name": "Prototype_Rock_Concrete_Brick"
    },
    {
      "x": -20,
      "y": 16,
      "z": 22,
      "name": "Prototype_Rock_Concrete_Brick"
    },
    {
      "x": -20,
      "y": 3,
      "z": 23,
      "name": "Prototype_Rock_Concrete_Brick"
    },
    {
      "x": -20,
      "y": 4,
      "z": 23,
      "name": "Prototype_Rock_Concrete_Brick"
    },
    {
      "x": -20,
      "y": 15,
      "z": 23,
      "name": "Prototype_Rock_Concrete_Brick"
    },
    {
      "x": -20,
      "y": 16,
      "z": 23,
      "name": "Prototype_Rock_Concrete_Brick"
    },
    {
      "x": -20,
      "y": 3,
      "z": 24,
      "name": "Prototype_Rock_Concrete_Brick"
    },
    {
      "x": -20,
      "y": 4,
      "z": 24,
      "name": "Prototype_Rock_Concrete_Brick"
    },
    {
      "x": -20,
      "y": 15,
      "z": 24,
      "name": "Prototype_Rock_Concrete_Brick"
    },
    {
      "x": -20,
      "y": 16,
      "z": 24,
      "name": "Prototype_Rock_Concrete_Brick"
    },
    {
      "x": -20,
      "y": 3,
      "z": 25,
      "name": "Prototype_Rock_Concrete_Brick"
    },
    {
      "x": -20,
      "y": 4,
      "z": 25,
      "name": "Prototype_Rock_Concrete_Brick"
    },
    {
      "x": -20,
      "y": 15,
      "z": 25,
      "name": "Prototype_Rock_Concrete_Brick"
    },
    {
      "x": -20,
      "y": 16,
      "z": 25,
      "name": "Prototype_Rock_Concrete_Brick"
    },
    {
      "x": -19,
      "y": 14,
      "z": 5,
      "name": "Prototype_Rock_Concrete_Brick"
    },
    {
      "x": -19,
      "y": 4,
      "z": 6,
      "name": "Prototype_Rock_Concrete_Brick"
    },
    {
      "x": -19,
      "y": 5,
      "z": 6,
      "name": "Prototype_Rock_Concrete_Brick"
    },
    {
      "x": -19,
      "y": 14,
      "z": 6,
      "name": "Prototype_Rock_Concrete_Brick"
    },
    {
      "x": -19,
      "y": 15,
      "z": 6,
      "name": "Prototype_Rock_Concrete_Brick"
    },
    {
      "x": -19,
      "y": 4,
      "z": 7,
      "name": "Prototype_Rock_Concrete_Brick"
    },
    {
      "x": -19,
      "y": 5,
      "z": 7,
      "name": "Prototype_Rock_Concrete_Brick"
    },
    {
      "x": -19,
      "y": 14,
      "z": 7,
      "name": "Prototype_Rock_Concrete_Brick"
    },
    {
      "x": -19,
      "y": 15,
      "z": 7,
      "name": "Prototype_Rock_Concrete_Brick"
    },
    {
      "x": -19,
      "y": 4,
      "z": 8,
      "name": "Prototype_Rock_Concrete_Brick"
    },
    {
      "x": -19,
      "y": 5,
      "z": 8,
      "name": "Prototype_Rock_Concrete_Brick"
    },
    {
      "x": -19,
      "y": 6,
      "z": 8,
      "name": "Prototype_Rock_Concrete_Brick"
    },
    {
      "x": -19,
      "y": 14,
      "z": 8,
      "name": "Prototype_Rock_Concrete_Brick"
    },
    {
      "x": -19,
      "y": 15,
      "z": 8,
      "name": "Prototype_Rock_Concrete_Brick"
    },
    {
      "x": -19,
      "y": 4,
      "z": 9,
      "name": "Prototype_Rock_Concrete_Brick"
    },
    {
      "x": -19,
      "y": 5,
      "z": 9,
      "name": "Prototype_Rock_Concrete_Brick"
    },
    {
      "x": -19,
      "y": 6,
      "z": 9,
      "name": "Prototype_Rock_Concrete_Brick"
    },
    {
      "x": -19,
      "y": 14,
      "z": 9,
      "name": "Prototype_Rock_Concrete_Brick"
    },
    {
      "x": -19,
      "y": 15,
      "z": 9,
      "name": "Prototype_Rock_Concrete_Brick"
    },
    {
      "x": -19,
      "y": 16,
      "z": 9,
      "name": "Prototype_Rock_Concrete_Brick"
    },
    {
      "x": -19,
      "y": 4,
      "z": 10,
      "name": "Prototype_Rock_Concrete_Brick"
    },
    {
      "x": -19,
      "y": 5,
      "z": 10,
      "name": "Prototype_Rock_Concrete_Brick"
    },
    {
      "x": -19,
      "y": 6,
      "z": 10,
      "name": "Prototype_Rock_Concrete_Brick"
    },
    {
      "x": -19,
      "y": 14,
      "z": 10,
      "name": "Prototype_Rock_Concrete_Brick"
    },
    {
      "x": -19,
      "y": 15,
      "z": 10,
      "name": "Prototype_Rock_Concrete_Brick"
    },
    {
      "x": -19,
      "y": 16,
      "z": 10,
      "name": "Prototype_Rock_Concrete_Brick"
    },
    {
      "x": -19,
      "y": 3,
      "z": 11,
      "name": "Prototype_Rock_Concrete_Brick"
    },
    {
      "x": -19,
      "y": 4,
      "z": 11,
      "name": "Prototype_Rock_Concrete_Brick"
    },
    {
      "x": -19,
      "y": 5,
      "z": 11,
      "name": "Prototype_Rock_Concrete_Brick"
    },
    {
      "x": -19,
      "y": 6,
      "z": 11,
      "name": "Prototype_Rock_Concrete_Brick"
    },
    {
      "x": -19,
      "y": 14,
      "z": 11,
      "name": "Prototype_Rock_Concrete_Brick"
    },
    {
      "x": -19,
      "y": 15,
      "z": 11,
      "name": "Prototype_Rock_Concrete_Brick"
    },
    {
      "x": -19,
      "y": 16,
      "z": 11,
      "name": "Prototype_Rock_Concrete_Brick"
    },
    {
      "x": -19,
      "y": 3,
      "z": 12,
      "name": "Prototype_Rock_Concrete_Brick"
    },
    {
      "x": -19,
      "y": 4,
      "z": 12,
      "name": "Prototype_Rock_Concrete_Brick"
    },
    {
      "x": -19,
      "y": 5,
      "z": 12,
      "name": "Prototype_Rock_Concrete_Brick"
    },
    {
      "x": -19,
      "y": 6,
      "z": 12,
      "name": "Prototype_Rock_Concrete_Brick"
    },
    {
      "x": -19,
      "y": 14,
      "z": 12,
      "name": "Prototype_Rock_Concrete_Brick"
    },
    {
      "x": -19,
      "y": 15,
      "z": 12,
      "name": "Prototype_Rock_Concrete_Brick"
    },
    {
      "x": -19,
      "y": 16,
      "z": 12,
      "name": "Prototype_Rock_Concrete_Brick"
    },
    {
      "x": -19,
      "y": 3,
      "z": 13,
      "name": "Prototype_Rock_Concrete_Brick"
    },
    {
      "x": -19,
      "y": 4,
      "z": 13,
      "name": "Prototype_Rock_Concrete_Brick"
    },
    {
      "x": -19,
      "y": 5,
      "z": 13,
      "name": "Prototype_Rock_Concrete_Brick"
    },
    {
      "x": -19,
      "y": 6,
      "z": 13,
      "name": "Prototype_Rock_Concrete_Brick"
    },
    {
      "x": -19,
      "y": 14,
      "z": 13,
      "name": "Prototype_Rock_Concrete_Brick"
    },
    {
      "x": -19,
      "y": 15,
      "z": 13,
      "name": "Prototype_Rock_Concrete_Brick"
    },
    {
      "x": -19,
      "y": 16,
      "z": 13,
      "name": "Prototype_Rock_Concrete_Brick"
    },
    {
      "x": -19,
      "y": 3,
      "z": 14,
      "name": "Prototype_Rock_Concrete_Brick"
    },
    {
      "x": -19,
      "y": 4,
      "z": 14,
      "name": "Prototype_Rock_Concrete_Brick"
    },
    {
      "x": -19,
      "y": 5,
      "z": 14,
      "name": "Prototype_Rock_Concrete_Brick"
    },
    {
      "x": -19,
      "y": 6,
      "z": 14,
      "name": "Prototype_Rock_Concrete_Brick"
    },
    {
      "x": -19,
      "y": 14,
      "z": 14,
      "name": "Prototype_Rock_Concrete_Brick"
    },
    {
      "x": -19,
      "y": 15,
      "z": 14,
      "name": "Prototype_Rock_Concrete_Brick"
    },
    {
      "x": -19,
      "y": 16,
      "z": 14,
      "name": "Prototype_Rock_Concrete_Brick"
    },
    {
      "x": -19,
      "y": 3,
      "z": 15,
      "name": "Prototype_Rock_Concrete_Brick"
    },
    {
      "x": -19,
      "y": 4,
      "z": 15,
      "name": "Prototype_Rock_Concrete_Brick"
    },
    {
      "x": -19,
      "y": 5,
      "z": 15,
      "name": "Prototype_Rock_Concrete_Brick"
    },
    {
      "x": -19,
      "y": 6,
      "z": 15,
      "name": "Prototype_Rock_Concrete_Brick"
    },
    {
      "x": -19,
      "y": 14,
      "z": 15,
      "name": "Prototype_Rock_Concrete_Brick"
    },
    {
      "x": -19,
      "y": 15,
      "z": 15,
      "name": "Prototype_Rock_Concrete_Brick"
    },
    {
      "x": -19,
      "y": 16,
      "z": 15,
      "name": "Prototype_Rock_Concrete_Brick"
    },
    {
      "x": -19,
      "y": 3,
      "z": 16,
      "name": "Prototype_Rock_Concrete_Brick"
    },
    {
      "x": -19,
      "y": 4,
      "z": 16,
      "name": "Prototype_Rock_Concrete_Brick"
    },
    {
      "x": -19,
      "y": 5,
      "z": 16,
      "name": "Prototype_Rock_Concrete_Brick"
    },
    {
      "x": -19,
      "y": 14,
      "z": 16,
      "name": "Prototype_Rock_Concrete_Brick"
    },
    {
      "x": -19,
      "y": 15,
      "z": 16,
      "name": "Prototype_Rock_Concrete_Brick"
    },
    {
      "x": -19,
      "y": 16,
      "z": 16,
      "name": "Prototype_Rock_Concrete_Brick"
    },
    {
      "x": -19,
      "y": 3,
      "z": 17,
      "name": "Prototype_Rock_Concrete_Brick"
    },
    {
      "x": -19,
      "y": 4,
      "z": 17,
      "name": "Prototype_Rock_Concrete_Brick"
    },
    {
      "x": -19,
      "y": 5,
      "z": 17,
      "name": "Prototype_Rock_Concrete_Brick"
    },
    {
      "x": -19,
      "y": 14,
      "z": 17,
      "name": "Prototype_Rock_Concrete_Brick"
    },
    {
      "x": -19,
      "y": 15,
      "z": 17,
      "name": "Prototype_Rock_Concrete_Brick"
    },
    {
      "x": -19,
      "y": 16,
      "z": 17,
      "name": "Prototype_Rock_Concrete_Brick"
    },
    {
      "x": -19,
      "y": 3,
      "z": 18,
      "name": "Prototype_Rock_Concrete_Brick"
    },
    {
      "x": -19,
      "y": 4,
      "z": 18,
      "name": "Prototype_Rock_Concrete_Brick"
    },
    {
      "x": -19,
      "y": 5,
      "z": 18,
      "name": "Prototype_Rock_Concrete_Brick"
    },
    {
      "x": -19,
      "y": 14,
      "z": 18,
      "name": "Prototype_Rock_Concrete_Brick"
    },
    {
      "x": -19,
      "y": 15,
      "z": 18,
      "name": "Prototype_Rock_Concrete_Brick"
    },
    {
      "x": -19,
      "y": 16,
      "z": 18,
      "name": "Prototype_Rock_Concrete_Brick"
    },
    {
      "x": -19,
      "y": 3,
      "z": 19,
      "name": "Prototype_Rock_Concrete_Brick"
    },
    {
      "x": -19,
      "y": 4,
      "z": 19,
      "name": "Prototype_Rock_Concrete_Brick"
    },
    {
      "x": -19,
      "y": 5,
      "z": 19,
      "name": "Prototype_Rock_Concrete_Brick"
    },
    {
      "x": -19,
      "y": 14,
      "z": 19,
      "name": "Prototype_Rock_Concrete_Brick"
    },
    {
      "x": -19,
      "y": 15,
      "z": 19,
      "name": "Prototype_Rock_Concrete_Brick"
    },
    {
      "x": -19,
      "y": 16,
      "z": 19,
      "name": "Prototype_Rock_Concrete_Brick"
    },
    {
      "x": -19,
      "y": 3,
      "z": 20,
      "name": "Prototype_Rock_Concrete_Brick"
    },
    {
      "x": -19,
      "y": 4,
      "z": 20,
      "name": "Prototype_Rock_Concrete_Brick"
    },
    {
      "x": -19,
      "y": 5,
      "z": 20,
      "name": "Prototype_Rock_Concrete_Brick"
    },
    {
      "x": -19,
      "y": 14,
      "z": 20,
      "name": "Prototype_Rock_Concrete_Brick"
    },
    {
      "x": -19,
      "y": 15,
      "z": 20,
      "name": "Prototype_Rock_Concrete_Brick"
    },
    {
      "x": -19,
      "y": 16,
      "z": 20,
      "name": "Prototype_Rock_Concrete_Brick"
    },
    {
      "x": -19,
      "y": 3,
      "z": 21,
      "name": "Prototype_Rock_Concrete_Brick"
    },
    {
      "x": -19,
      "y": 4,
      "z": 21,
      "name": "Prototype_Rock_Concrete_Brick"
    },
    {
      "x": -19,
      "y": 14,
      "z": 21,
      "name": "Prototype_Rock_Concrete_Brick"
    },
    {
      "x": -19,
      "y": 15,
      "z": 21,
      "name": "Prototype_Rock_Concrete_Brick"
    },
    {
      "x": -19,
      "y": 16,
      "z": 21,
      "name": "Prototype_Rock_Concrete_Brick"
    },
    {
      "x": -19,
      "y": 4,
      "z": 22,
      "name": "Prototype_Rock_Concrete_Brick"
    },
    {
      "x": -19,
      "y": 15,
      "z": 22,
      "name": "Prototype_Rock_Concrete_Brick"
    },
    {
      "x": -18,
      "y": 6,
      "z": 2,
      "name": "Prototype_Rock_Concrete_Brick"
    },
    {
      "x": -18,
      "y": 13,
      "z": 2,
      "name": "Prototype_Rock_Concrete_Brick"
    },
    {
      "x": -18,
      "y": 14,
      "z": 2,
      "name": "Prototype_Rock_Concrete_Brick"
    },
    {
      "x": -18,
      "y": 5,
      "z": 3,
      "name": "Prototype_Rock_Concrete_Brick"
    },
    {
      "x": -18,
      "y": 6,
      "z": 3,
      "name": "Prototype_Rock_Concrete_Brick"
    },
    {
      "x": -18,
      "y": 13,
      "z": 3,
      "name": "Prototype_Rock_Concrete_Brick"
    },
    {
      "x": -18,
      "y": 14,
      "z": 3,
      "name": "Prototype_Rock_Concrete_Brick"
    },
    {
      "x": -18,
      "y": 5,
      "z": 4,
      "name": "Prototype_Rock_Concrete_Brick"
    },
    {
      "x": -18,
      "y": 6,
      "z": 4,
      "name": "Prototype_Rock_Concrete_Brick"
    },
    {
      "x": -18,
      "y": 13,
      "z": 4,
      "name": "Prototype_Rock_Concrete_Brick"
    },
    {
      "x": -18,
      "y": 14,
      "z": 4,
      "name": "Prototype_Rock_Concrete_Brick"
    },
    {
      "x": -18,
      "y": 5,
      "z": 5,
      "name": "Prototype_Rock_Concrete_Brick"
    },
    {
      "x": -18,
      "y": 6,
      "z": 5,
      "name": "Prototype_Rock_Concrete_Brick"
    },
    {
      "x": -18,
      "y": 13,
      "z": 5,
      "name": "Prototype_Rock_Concrete_Brick"
    },
    {
      "x": -18,
      "y": 14,
      "z": 5,
      "name": "Prototype_Rock_Concrete_Brick"
    },
    {
      "x": -18,
      "y": 15,
      "z": 5,
      "name": "Prototype_Rock_Concrete_Brick"
    },
    {
      "x": -18,
      "y": 4,
      "z": 6,
      "name": "Prototype_Rock_Concrete_Brick"
    },
    {
      "x": -18,
      "y": 5,
      "z": 6,
      "name": "Prototype_Rock_Concrete_Brick"
    },
    {
      "x": -18,
      "y": 6,
      "z": 6,
      "name": "Prototype_Rock_Concrete_Brick"
    },
    {
      "x": -18,
      "y": 13,
      "z": 6,
      "name": "Prototype_Rock_Concrete_Brick"
    },
    {
      "x": -18,
      "y": 14,
      "z": 6,
      "name": "Prototype_Rock_Concrete_Brick"
    },
    {
      "x": -18,
      "y": 15,
      "z": 6,
      "name": "Prototype_Rock_Concrete_Brick"
    },
    {
      "x": -18,
      "y": 4,
      "z": 7,
      "name": "Prototype_Rock_Concrete_Brick"
    },
    {
      "x": -18,
      "y": 5,
      "z": 7,
      "name": "Prototype_Rock_Concrete_Brick"
    },
    {
      "x": -18,
      "y": 6,
      "z": 7,
      "name": "Prototype_Rock_Concrete_Brick"
    },
    {
      "x": -18,
      "y": 13,
      "z": 7,
      "name": "Prototype_Rock_Concrete_Brick"
    },
    {
      "x": -18,
      "y": 14,
      "z": 7,
      "name": "Prototype_Rock_Concrete_Brick"
    },
    {
      "x": -18,
      "y": 15,
      "z": 7,
      "name": "Prototype_Rock_Concrete_Brick"
    },
    {
      "x": -18,
      "y": 4,
      "z": 8,
      "name": "Prototype_Rock_Concrete_Brick"
    },
    {
      "x": -18,
      "y": 5,
      "z": 8,
      "name": "Prototype_Rock_Concrete_Brick"
    },
    {
      "x": -18,
      "y": 6,
      "z": 8,
      "name": "Prototype_Rock_Concrete_Brick"
    },
    {
      "x": -18,
      "y": 13,
      "z": 8,
      "name": "Prototype_Rock_Concrete_Brick"
    },
    {
      "x": -18,
      "y": 14,
      "z": 8,
      "name": "Prototype_Rock_Concrete_Brick"
    },
    {
      "x": -18,
      "y": 15,
      "z": 8,
      "name": "Prototype_Rock_Concrete_Brick"
    },
    {
      "x": -18,
      "y": 4,
      "z": 9,
      "name": "Prototype_Rock_Concrete_Brick"
    },
    {
      "x": -18,
      "y": 5,
      "z": 9,
      "name": "Prototype_Rock_Concrete_Brick"
    },
    {
      "x": -18,
      "y": 6,
      "z": 9,
      "name": "Prototype_Rock_Concrete_Brick"
    },
    {
      "x": -18,
      "y": 13,
      "z": 9,
      "name": "Prototype_Rock_Concrete_Brick"
    },
    {
      "x": -18,
      "y": 14,
      "z": 9,
      "name": "Prototype_Rock_Concrete_Brick"
    },
    {
      "x": -18,
      "y": 15,
      "z": 9,
      "name": "Prototype_Rock_Concrete_Brick"
    },
    {
      "x": -18,
      "y": 4,
      "z": 10,
      "name": "Prototype_Rock_Concrete_Brick"
    },
    {
      "x": -18,
      "y": 5,
      "z": 10,
      "name": "Prototype_Rock_Concrete_Brick"
    },
    {
      "x": -18,
      "y": 6,
      "z": 10,
      "name": "Prototype_Rock_Concrete_Brick"
    },
    {
      "x": -18,
      "y": 13,
      "z": 10,
      "name": "Prototype_Rock_Concrete_Brick"
    },
    {
      "x": -18,
      "y": 14,
      "z": 10,
      "name": "Prototype_Rock_Concrete_Brick"
    },
    {
      "x": -18,
      "y": 15,
      "z": 10,
      "name": "Prototype_Rock_Concrete_Brick"
    },
    {
      "x": -18,
      "y": 4,
      "z": 11,
      "name": "Prototype_Rock_Concrete_Brick"
    },
    {
      "x": -18,
      "y": 5,
      "z": 11,
      "name": "Prototype_Rock_Concrete_Brick"
    },
    {
      "x": -18,
      "y": 6,
      "z": 11,
      "name": "Prototype_Rock_Concrete_Brick"
    },
    {
      "x": -18,
      "y": 13,
      "z": 11,
      "name": "Prototype_Rock_Concrete_Brick"
    },
    {
      "x": -18,
      "y": 14,
      "z": 11,
      "name": "Prototype_Rock_Concrete_Brick"
    },
    {
      "x": -18,
      "y": 15,
      "z": 11,
      "name": "Prototype_Rock_Concrete_Brick"
    },
    {
      "x": -18,
      "y": 4,
      "z": 12,
      "name": "Prototype_Rock_Concrete_Brick"
    },
    {
      "x": -18,
      "y": 5,
      "z": 12,
      "name": "Prototype_Rock_Concrete_Brick"
    },
    {
      "x": -18,
      "y": 6,
      "z": 12,
      "name": "Prototype_Rock_Concrete_Brick"
    },
    {
      "x": -18,
      "y": 13,
      "z": 12,
      "name": "Prototype_Rock_Concrete_Brick"
    },
    {
      "x": -18,
      "y": 14,
      "z": 12,
      "name": "Prototype_Rock_Concrete_Brick"
    },
    {
      "x": -18,
      "y": 15,
      "z": 12,
      "name": "Prototype_Rock_Concrete_Brick"
    },
    {
      "x": -18,
      "y": 4,
      "z": 13,
      "name": "Prototype_Rock_Concrete_Brick"
    },
    {
      "x": -18,
      "y": 5,
      "z": 13,
      "name": "Prototype_Rock_Concrete_Brick"
    },
    {
      "x": -18,
      "y": 6,
      "z": 13,
      "name": "Prototype_Rock_Concrete_Brick"
    },
    {
      "x": -18,
      "y": 13,
      "z": 13,
      "name": "Prototype_Rock_Concrete_Brick"
    },
    {
      "x": -18,
      "y": 14,
      "z": 13,
      "name": "Prototype_Rock_Concrete_Brick"
    },
    {
      "x": -18,
      "y": 15,
      "z": 13,
      "name": "Prototype_Rock_Concrete_Brick"
    },
    {
      "x": -18,
      "y": 4,
      "z": 14,
      "name": "Prototype_Rock_Concrete_Brick"
    },
    {
      "x": -18,
      "y": 5,
      "z": 14,
      "name": "Prototype_Rock_Concrete_Brick"
    },
    {
      "x": -18,
      "y": 6,
      "z": 14,
      "name": "Prototype_Rock_Concrete_Brick"
    },
    {
      "x": -18,
      "y": 13,
      "z": 14,
      "name": "Prototype_Rock_Concrete_Brick"
    },
    {
      "x": -18,
      "y": 14,
      "z": 14,
      "name": "Prototype_Rock_Concrete_Brick"
    },
    {
      "x": -18,
      "y": 15,
      "z": 14,
      "name": "Prototype_Rock_Concrete_Brick"
    },
    {
      "x": -18,
      "y": 4,
      "z": 15,
      "name": "Prototype_Rock_Concrete_Brick"
    },
    {
      "x": -18,
      "y": 5,
      "z": 15,
      "name": "Prototype_Rock_Concrete_Brick"
    },
    {
      "x": -18,
      "y": 6,
      "z": 15,
      "name": "Prototype_Rock_Concrete_Brick"
    },
    {
      "x": -18,
      "y": 13,
      "z": 15,
      "name": "Prototype_Rock_Concrete_Brick"
    },
    {
      "x": -18,
      "y": 14,
      "z": 15,
      "name": "Prototype_Rock_Concrete_Brick"
    },
    {
      "x": -18,
      "y": 15,
      "z": 15,
      "name": "Prototype_Rock_Concrete_Brick"
    },
    {
      "x": -18,
      "y": 4,
      "z": 16,
      "name": "Prototype_Rock_Concrete_Brick"
    },
    {
      "x": -18,
      "y": 5,
      "z": 16,
      "name": "Prototype_Rock_Concrete_Brick"
    },
    {
      "x": -18,
      "y": 6,
      "z": 16,
      "name": "Prototype_Rock_Concrete_Brick"
    },
    {
      "x": -18,
      "y": 13,
      "z": 16,
      "name": "Prototype_Rock_Concrete_Brick"
    },
    {
      "x": -18,
      "y": 14,
      "z": 16,
      "name": "Prototype_Rock_Concrete_Brick"
    },
    {
      "x": -18,
      "y": 15,
      "z": 16,
      "name": "Prototype_Rock_Concrete_Brick"
    },
    {
      "x": -18,
      "y": 4,
      "z": 17,
      "name": "Prototype_Rock_Concrete_Brick"
    },
    {
      "x": -18,
      "y": 5,
      "z": 17,
      "name": "Prototype_Rock_Concrete_Brick"
    },
    {
      "x": -18,
      "y": 6,
      "z": 17,
      "name": "Prototype_Rock_Concrete_Brick"
    },
    {
      "x": -18,
      "y": 14,
      "z": 17,
      "name": "Prototype_Rock_Concrete_Brick"
    },
    {
      "x": -18,
      "y": 15,
      "z": 17,
      "name": "Prototype_Rock_Concrete_Brick"
    },
    {
      "x": -18,
      "y": 4,
      "z": 18,
      "name": "Prototype_Rock_Concrete_Brick"
    },
    {
      "x": -18,
      "y": 5,
      "z": 18,
      "name": "Prototype_Rock_Concrete_Brick"
    },
    {
      "x": -18,
      "y": 14,
      "z": 18,
      "name": "Prototype_Rock_Concrete_Brick"
    },
    {
      "x": -18,
      "y": 15,
      "z": 18,
      "name": "Prototype_Rock_Concrete_Brick"
    },
    {
      "x": -18,
      "y": 4,
      "z": 19,
      "name": "Prototype_Rock_Concrete_Brick"
    },
    {
      "x": -18,
      "y": 5,
      "z": 19,
      "name": "Prototype_Rock_Concrete_Brick"
    },
    {
      "x": -18,
      "y": 14,
      "z": 19,
      "name": "Prototype_Rock_Concrete_Brick"
    },
    {
      "x": -18,
      "y": 15,
      "z": 19,
      "name": "Prototype_Rock_Concrete_Brick"
    },
    {
      "x": -18,
      "y": 15,
      "z": 20,
      "name": "Prototype_Rock_Concrete_Brick"
    },
    {
      "x": -17,
      "y": 6,
      "z": 1,
      "name": "Prototype_Rock_Concrete_Brick"
    },
    {
      "x": -17,
      "y": 13,
      "z": 1,
      "name": "Prototype_Rock_Concrete_Brick"
    },
    {
      "x": -17,
      "y": 5,
      "z": 2,
      "name": "Prototype_Rock_Concrete_Brick"
    },
    {
      "x": -17,
      "y": 6,
      "z": 2,
      "name": "Prototype_Rock_Concrete_Brick"
    },
    {
      "x": -17,
      "y": 7,
      "z": 2,
      "name": "Prototype_Rock_Concrete_Brick"
    },
    {
      "x": -17,
      "y": 13,
      "z": 2,
      "name": "Prototype_Rock_Concrete_Brick"
    },
    {
      "x": -17,
      "y": 14,
      "z": 2,
      "name": "Prototype_Rock_Concrete_Brick"
    },
    {
      "x": -17,
      "y": 5,
      "z": 3,
      "name": "Prototype_Rock_Concrete_Brick"
    },
    {
      "x": -17,
      "y": 6,
      "z": 3,
      "name": "Prototype_Rock_Concrete_Brick"
    },
    {
      "x": -17,
      "y": 7,
      "z": 3,
      "name": "Prototype_Rock_Concrete_Brick"
    },
    {
      "x": -17,
      "y": 13,
      "z": 3,
      "name": "Prototype_Rock_Concrete_Brick"
    },
    {
      "x": -17,
      "y": 14,
      "z": 3,
      "name": "Prototype_Rock_Concrete_Brick"
    },
    {
      "x": -17,
      "y": 5,
      "z": 4,
      "name": "Prototype_Rock_Concrete_Brick"
    },
    {
      "x": -17,
      "y": 6,
      "z": 4,
      "name": "Prototype_Rock_Concrete_Brick"
    },
    {
      "x": -17,
      "y": 7,
      "z": 4,
      "name": "Prototype_Rock_Concrete_Brick"
    },
    {
      "x": -17,
      "y": 12,
      "z": 4,
      "name": "Prototype_Rock_Concrete_Brick"
    },
    {
      "x": -17,
      "y": 13,
      "z": 4,
      "name": "Prototype_Rock_Concrete_Brick"
    },
    {
      "x": -17,
      "y": 14,
      "z": 4,
      "name": "Prototype_Rock_Concrete_Brick"
    },
    {
      "x": -17,
      "y": 5,
      "z": 5,
      "name": "Prototype_Rock_Concrete_Brick"
    },
    {
      "x": -17,
      "y": 6,
      "z": 5,
      "name": "Prototype_Rock_Concrete_Brick"
    },
    {
      "x": -17,
      "y": 7,
      "z": 5,
      "name": "Prototype_Rock_Concrete_Brick"
    },
    {
      "x": -17,
      "y": 12,
      "z": 5,
      "name": "Prototype_Rock_Concrete_Brick"
    },
    {
      "x": -17,
      "y": 13,
      "z": 5,
      "name": "Prototype_Rock_Concrete_Brick"
    },
    {
      "x": -17,
      "y": 14,
      "z": 5,
      "name": "Prototype_Rock_Concrete_Brick"
    },
    {
      "x": -17,
      "y": 5,
      "z": 6,
      "name": "Prototype_Rock_Concrete_Brick"
    },
    {
      "x": -17,
      "y": 6,
      "z": 6,
      "name": "Prototype_Rock_Concrete_Brick"
    },
    {
      "x": -17,
      "y": 7,
      "z": 6,
      "name": "Prototype_Rock_Concrete_Brick"
    },
    {
      "x": -17,
      "y": 12,
      "z": 6,
      "name": "Prototype_Rock_Concrete_Brick"
    },
    {
      "x": -17,
      "y": 13,
      "z": 6,
      "name": "Prototype_Rock_Concrete_Brick"
    },
    {
      "x": -17,
      "y": 14,
      "z": 6,
      "name": "Prototype_Rock_Concrete_Brick"
    },
    {
      "x": -17,
      "y": 5,
      "z": 7,
      "name": "Prototype_Rock_Concrete_Brick"
    },
    {
      "x": -17,
      "y": 6,
      "z": 7,
      "name": "Prototype_Rock_Concrete_Brick"
    },
    {
      "x": -17,
      "y": 7,
      "z": 7,
      "name": "Prototype_Rock_Concrete_Brick"
    },
    {
      "x": -17,
      "y": 12,
      "z": 7,
      "name": "Prototype_Rock_Concrete_Brick"
    },
    {
      "x": -17,
      "y": 13,
      "z": 7,
      "name": "Prototype_Rock_Concrete_Brick"
    },
    {
      "x": -17,
      "y": 14,
      "z": 7,
      "name": "Prototype_Rock_Concrete_Brick"
    },
    {
      "x": -17,
      "y": 5,
      "z": 8,
      "name": "Prototype_Rock_Concrete_Brick"
    },
    {
      "x": -17,
      "y": 6,
      "z": 8,
      "name": "Prototype_Rock_Concrete_Brick"
    },
    {
      "x": -17,
      "y": 7,
      "z": 8,
      "name": "Prototype_Rock_Concrete_Brick"
    },
    {
      "x": -17,
      "y": 12,
      "z": 8,
      "name": "Prototype_Rock_Concrete_Brick"
    },
    {
      "x": -17,
      "y": 13,
      "z": 8,
      "name": "Prototype_Rock_Concrete_Brick"
    },
    {
      "x": -17,
      "y": 14,
      "z": 8,
      "name": "Prototype_Rock_Concrete_Brick"
    },
    {
      "x": -17,
      "y": 5,
      "z": 9,
      "name": "Prototype_Rock_Concrete_Brick"
    },
    {
      "x": -17,
      "y": 6,
      "z": 9,
      "name": "Prototype_Rock_Concrete_Brick"
    },
    {
      "x": -17,
      "y": 7,
      "z": 9,
      "name": "Prototype_Rock_Concrete_Brick"
    },
    {
      "x": -17,
      "y": 12,
      "z": 9,
      "name": "Prototype_Rock_Concrete_Brick"
    },
    {
      "x": -17,
      "y": 13,
      "z": 9,
      "name": "Prototype_Rock_Concrete_Brick"
    },
    {
      "x": -17,
      "y": 14,
      "z": 9,
      "name": "Prototype_Rock_Concrete_Brick"
    },
    {
      "x": -17,
      "y": 5,
      "z": 10,
      "name": "Prototype_Rock_Concrete_Brick"
    },
    {
      "x": -17,
      "y": 6,
      "z": 10,
      "name": "Prototype_Rock_Concrete_Brick"
    },
    {
      "x": -17,
      "y": 7,
      "z": 10,
      "name": "Prototype_Rock_Concrete_Brick"
    },
    {
      "x": -17,
      "y": 12,
      "z": 10,
      "name": "Prototype_Rock_Concrete_Brick"
    },
    {
      "x": -17,
      "y": 13,
      "z": 10,
      "name": "Prototype_Rock_Concrete_Brick"
    },
    {
      "x": -17,
      "y": 14,
      "z": 10,
      "name": "Prototype_Rock_Concrete_Brick"
    },
    {
      "x": -17,
      "y": 5,
      "z": 11,
      "name": "Prototype_Rock_Concrete_Brick"
    },
    {
      "x": -17,
      "y": 6,
      "z": 11,
      "name": "Prototype_Rock_Concrete_Brick"
    },
    {
      "x": -17,
      "y": 7,
      "z": 11,
      "name": "Prototype_Rock_Concrete_Brick"
    },
    {
      "x": -17,
      "y": 12,
      "z": 11,
      "name": "Prototype_Rock_Concrete_Brick"
    },
    {
      "x": -17,
      "y": 13,
      "z": 11,
      "name": "Prototype_Rock_Concrete_Brick"
    },
    {
      "x": -17,
      "y": 14,
      "z": 11,
      "name": "Prototype_Rock_Concrete_Brick"
    },
    {
      "x": -17,
      "y": 5,
      "z": 12,
      "name": "Prototype_Rock_Concrete_Brick"
    },
    {
      "x": -17,
      "y": 6,
      "z": 12,
      "name": "Prototype_Rock_Concrete_Brick"
    },
    {
      "x": -17,
      "y": 7,
      "z": 12,
      "name": "Prototype_Rock_Concrete_Brick"
    },
    {
      "x": -17,
      "y": 13,
      "z": 12,
      "name": "Prototype_Rock_Concrete_Brick"
    },
    {
      "x": -17,
      "y": 14,
      "z": 12,
      "name": "Prototype_Rock_Concrete_Brick"
    },
    {
      "x": -17,
      "y": 5,
      "z": 13,
      "name": "Prototype_Rock_Concrete_Brick"
    },
    {
      "x": -17,
      "y": 6,
      "z": 13,
      "name": "Prototype_Rock_Concrete_Brick"
    },
    {
      "x": -17,
      "y": 7,
      "z": 13,
      "name": "Prototype_Rock_Concrete_Brick"
    },
    {
      "x": -17,
      "y": 13,
      "z": 13,
      "name": "Prototype_Rock_Concrete_Brick"
    },
    {
      "x": -17,
      "y": 14,
      "z": 13,
      "name": "Prototype_Rock_Concrete_Brick"
    },
    {
      "x": -17,
      "y": 5,
      "z": 14,
      "name": "Prototype_Rock_Concrete_Brick"
    },
    {
      "x": -17,
      "y": 6,
      "z": 14,
      "name": "Prototype_Rock_Concrete_Brick"
    },
    {
      "x": -17,
      "y": 13,
      "z": 14,
      "name": "Prototype_Rock_Concrete_Brick"
    },
    {
      "x": -17,
      "y": 14,
      "z": 14,
      "name": "Prototype_Rock_Concrete_Brick"
    },
    {
      "x": -17,
      "y": 5,
      "z": 15,
      "name": "Prototype_Rock_Concrete_Brick"
    },
    {
      "x": -17,
      "y": 6,
      "z": 15,
      "name": "Prototype_Rock_Concrete_Brick"
    },
    {
      "x": -17,
      "y": 13,
      "z": 15,
      "name": "Prototype_Rock_Concrete_Brick"
    },
    {
      "x": -17,
      "y": 14,
      "z": 15,
      "name": "Prototype_Rock_Concrete_Brick"
    },
    {
      "x": -17,
      "y": 5,
      "z": 16,
      "name": "Prototype_Rock_Concrete_Brick"
    },
    {
      "x": -17,
      "y": 6,
      "z": 16,
      "name": "Prototype_Rock_Concrete_Brick"
    },
    {
      "x": -17,
      "y": 13,
      "z": 16,
      "name": "Prototype_Rock_Concrete_Brick"
    },
    {
      "x": -17,
      "y": 14,
      "z": 16,
      "name": "Prototype_Rock_Concrete_Brick"
    },
    {
      "x": -16,
      "y": 6,
      "z": 0,
      "name": "Prototype_Rock_Concrete_Brick"
    },
    {
      "x": -16,
      "y": 7,
      "z": 0,
      "name": "Prototype_Rock_Concrete_Brick"
    },
    {
      "x": -16,
      "y": 13,
      "z": 0,
      "name": "Prototype_Rock_Concrete_Brick"
    },
    {
      "x": -16,
      "y": 6,
      "z": 1,
      "name": "Prototype_Rock_Concrete_Brick"
    },
    {
      "x": -16,
      "y": 7,
      "z": 1,
      "name": "Prototype_Rock_Concrete_Brick"
    },
    {
      "x": -16,
      "y": 12,
      "z": 1,
      "name": "Prototype_Rock_Concrete_Brick"
    },
    {
      "x": -16,
      "y": 13,
      "z": 1,
      "name": "Prototype_Rock_Concrete_Brick"
    },
    {
      "x": -16,
      "y": 14,
      "z": 1,
      "name": "Prototype_Rock_Concrete_Brick"
    },
    {
      "x": -16,
      "y": 6,
      "z": 2,
      "name": "Prototype_Rock_Concrete_Brick"
    },
    {
      "x": -16,
      "y": 7,
      "z": 2,
      "name": "Prototype_Rock_Concrete_Brick"
    },
    {
      "x": -16,
      "y": 12,
      "z": 2,
      "name": "Prototype_Rock_Concrete_Brick"
    },
    {
      "x": -16,
      "y": 13,
      "z": 2,
      "name": "Prototype_Rock_Concrete_Brick"
    },
    {
      "x": -16,
      "y": 14,
      "z": 2,
      "name": "Prototype_Rock_Concrete_Brick"
    },
    {
      "x": -16,
      "y": 5,
      "z": 3,
      "name": "Prototype_Rock_Concrete_Brick"
    },
    {
      "x": -16,
      "y": 6,
      "z": 3,
      "name": "Prototype_Rock_Concrete_Brick"
    },
    {
      "x": -16,
      "y": 7,
      "z": 3,
      "name": "Prototype_Rock_Concrete_Brick"
    },
    {
      "x": -16,
      "y": 12,
      "z": 3,
      "name": "Prototype_Rock_Concrete_Brick"
    },
    {
      "x": -16,
      "y": 13,
      "z": 3,
      "name": "Prototype_Rock_Concrete_Brick"
    },
    {
      "x": -16,
      "y": 14,
      "z": 3,
      "name": "Prototype_Rock_Concrete_Brick"
    },
    {
      "x": -16,
      "y": 5,
      "z": 4,
      "name": "Prototype_Rock_Concrete_Brick"
    },
    {
      "x": -16,
      "y": 6,
      "z": 4,
      "name": "Prototype_Rock_Concrete_Brick"
    },
    {
      "x": -16,
      "y": 7,
      "z": 4,
      "name": "Prototype_Rock_Concrete_Brick"
    },
    {
      "x": -16,
      "y": 12,
      "z": 4,
      "name": "Prototype_Rock_Concrete_Brick"
    },
    {
      "x": -16,
      "y": 13,
      "z": 4,
      "name": "Prototype_Rock_Concrete_Brick"
    },
    {
      "x": -16,
      "y": 14,
      "z": 4,
      "name": "Prototype_Rock_Concrete_Brick"
    },
    {
      "x": -16,
      "y": 5,
      "z": 5,
      "name": "Prototype_Rock_Concrete_Brick"
    },
    {
      "x": -16,
      "y": 6,
      "z": 5,
      "name": "Prototype_Rock_Concrete_Brick"
    },
    {
      "x": -16,
      "y": 7,
      "z": 5,
      "name": "Prototype_Rock_Concrete_Brick"
    },
    {
      "x": -16,
      "y": 12,
      "z": 5,
      "name": "Prototype_Rock_Concrete_Brick"
    },
    {
      "x": -16,
      "y": 13,
      "z": 5,
      "name": "Prototype_Rock_Concrete_Brick"
    },
    {
      "x": -16,
      "y": 14,
      "z": 5,
      "name": "Prototype_Rock_Concrete_Brick"
    },
    {
      "x": -16,
      "y": 5,
      "z": 6,
      "name": "Prototype_Rock_Concrete_Brick"
    },
    {
      "x": -16,
      "y": 6,
      "z": 6,
      "name": "Prototype_Rock_Concrete_Brick"
    },
    {
      "x": -16,
      "y": 7,
      "z": 6,
      "name": "Prototype_Rock_Concrete_Brick"
    },
    {
      "x": -16,
      "y": 12,
      "z": 6,
      "name": "Prototype_Rock_Concrete_Brick"
    },
    {
      "x": -16,
      "y": 13,
      "z": 6,
      "name": "Prototype_Rock_Concrete_Brick"
    },
    {
      "x": -16,
      "y": 14,
      "z": 6,
      "name": "Prototype_Rock_Concrete_Brick"
    },
    {
      "x": -16,
      "y": 5,
      "z": 7,
      "name": "Prototype_Rock_Concrete_Brick"
    },
    {
      "x": -16,
      "y": 6,
      "z": 7,
      "name": "Prototype_Rock_Concrete_Brick"
    },
    {
      "x": -16,
      "y": 7,
      "z": 7,
      "name": "Prototype_Rock_Concrete_Brick"
    },
    {
      "x": -16,
      "y": 12,
      "z": 7,
      "name": "Prototype_Rock_Concrete_Brick"
    },
    {
      "x": -16,
      "y": 13,
      "z": 7,
      "name": "Prototype_Rock_Concrete_Brick"
    },
    {
      "x": -16,
      "y": 14,
      "z": 7,
      "name": "Prototype_Rock_Concrete_Brick"
    },
    {
      "x": -16,
      "y": 5,
      "z": 8,
      "name": "Prototype_Rock_Concrete_Brick"
    },
    {
      "x": -16,
      "y": 6,
      "z": 8,
      "name": "Prototype_Rock_Concrete_Brick"
    },
    {
      "x": -16,
      "y": 7,
      "z": 8,
      "name": "Prototype_Rock_Concrete_Brick"
    },
    {
      "x": -16,
      "y": 12,
      "z": 8,
      "name": "Prototype_Rock_Concrete_Brick"
    },
    {
      "x": -16,
      "y": 13,
      "z": 8,
      "name": "Prototype_Rock_Concrete_Brick"
    },
    {
      "x": -16,
      "y": 14,
      "z": 8,
      "name": "Prototype_Rock_Concrete_Brick"
    },
    {
      "x": -16,
      "y": 5,
      "z": 9,
      "name": "Prototype_Rock_Concrete_Brick"
    },
    {
      "x": -16,
      "y": 6,
      "z": 9,
      "name": "Prototype_Rock_Concrete_Brick"
    },
    {
      "x": -16,
      "y": 7,
      "z": 9,
      "name": "Prototype_Rock_Concrete_Brick"
    },
    {
      "x": -16,
      "y": 12,
      "z": 9,
      "name": "Prototype_Rock_Concrete_Brick"
    },
    {
      "x": -16,
      "y": 13,
      "z": 9,
      "name": "Prototype_Rock_Concrete_Brick"
    },
    {
      "x": -16,
      "y": 14,
      "z": 9,
      "name": "Prototype_Rock_Concrete_Brick"
    },
    {
      "x": -16,
      "y": 5,
      "z": 10,
      "name": "Prototype_Rock_Concrete_Brick"
    },
    {
      "x": -16,
      "y": 6,
      "z": 10,
      "name": "Prototype_Rock_Concrete_Brick"
    },
    {
      "x": -16,
      "y": 7,
      "z": 10,
      "name": "Prototype_Rock_Concrete_Brick"
    },
    {
      "x": -16,
      "y": 12,
      "z": 10,
      "name": "Prototype_Rock_Concrete_Brick"
    },
    {
      "x": -16,
      "y": 13,
      "z": 10,
      "name": "Prototype_Rock_Concrete_Brick"
    },
    {
      "x": -16,
      "y": 14,
      "z": 10,
      "name": "Prototype_Rock_Concrete_Brick"
    },
    {
      "x": -16,
      "y": 5,
      "z": 11,
      "name": "Prototype_Rock_Concrete_Brick"
    },
    {
      "x": -16,
      "y": 6,
      "z": 11,
      "name": "Prototype_Rock_Concrete_Brick"
    },
    {
      "x": -16,
      "y": 7,
      "z": 11,
      "name": "Prototype_Rock_Concrete_Brick"
    },
    {
      "x": -16,
      "y": 12,
      "z": 11,
      "name": "Prototype_Rock_Concrete_Brick"
    },
    {
      "x": -16,
      "y": 13,
      "z": 11,
      "name": "Prototype_Rock_Concrete_Brick"
    },
    {
      "x": -16,
      "y": 14,
      "z": 11,
      "name": "Prototype_Rock_Concrete_Brick"
    },
    {
      "x": -16,
      "y": 6,
      "z": 12,
      "name": "Prototype_Rock_Concrete_Brick"
    },
    {
      "x": -16,
      "y": 7,
      "z": 12,
      "name": "Prototype_Rock_Concrete_Brick"
    },
    {
      "x": -16,
      "y": 12,
      "z": 12,
      "name": "Prototype_Rock_Concrete_Brick"
    },
    {
      "x": -16,
      "y": 13,
      "z": 12,
      "name": "Prototype_Rock_Concrete_Brick"
    },
    {
      "x": -16,
      "y": 14,
      "z": 12,
      "name": "Prototype_Rock_Concrete_Brick"
    },
    {
      "x": -16,
      "y": 6,
      "z": 13,
      "name": "Prototype_Rock_Concrete_Brick"
    },
    {
      "x": -16,
      "y": 7,
      "z": 13,
      "name": "Prototype_Rock_Concrete_Brick"
    },
    {
      "x": -16,
      "y": 12,
      "z": 13,
      "name": "Prototype_Rock_Concrete_Brick"
    },
    {
      "x": -16,
      "y": 13,
      "z": 13,
      "name": "Prototype_Rock_Concrete_Brick"
    },
    {
      "x": -16,
      "y": 14,
      "z": 13,
      "name": "Prototype_Rock_Concrete_Brick"
    },
    {
      "x": -16,
      "y": 6,
      "z": 14,
      "name": "Prototype_Rock_Concrete_Brick"
    },
    {
      "x": -16,
      "y": 13,
      "z": 14,
      "name": "Prototype_Rock_Concrete_Brick"
    },
    {
      "x": -15,
      "y": 6,
      "z": 0,
      "name": "Prototype_Rock_Concrete_Brick"
    },
    {
      "x": -15,
      "y": 7,
      "z": 0,
      "name": "Prototype_Rock_Concrete_Brick"
    },
    {
      "x": -15,
      "y": 12,
      "z": 0,
      "name": "Prototype_Rock_Concrete_Brick"
    },
    {
      "x": -15,
      "y": 13,
      "z": 0,
      "name": "Prototype_Rock_Concrete_Brick"
    },
    {
      "x": -15,
      "y": 6,
      "z": 1,
      "name": "Prototype_Rock_Concrete_Brick"
    },
    {
      "x": -15,
      "y": 7,
      "z": 1,
      "name": "Prototype_Rock_Concrete_Brick"
    },
    {
      "x": -15,
      "y": 12,
      "z": 1,
      "name": "Prototype_Rock_Concrete_Brick"
    },
    {
      "x": -15,
      "y": 13,
      "z": 1,
      "name": "Prototype_Rock_Concrete_Brick"
    },
    {
      "x": -15,
      "y": 6,
      "z": 2,
      "name": "Prototype_Rock_Concrete_Brick"
    },
    {
      "x": -15,
      "y": 7,
      "z": 2,
      "name": "Prototype_Rock_Concrete_Brick"
    },
    {
      "x": -15,
      "y": 12,
      "z": 2,
      "name": "Prototype_Rock_Concrete_Brick"
    },
    {
      "x": -15,
      "y": 13,
      "z": 2,
      "name": "Prototype_Rock_Concrete_Brick"
    },
    {
      "x": -15,
      "y": 6,
      "z": 3,
      "name": "Prototype_Rock_Concrete_Brick"
    },
    {
      "x": -15,
      "y": 7,
      "z": 3,
      "name": "Prototype_Rock_Concrete_Brick"
    },
    {
      "x": -15,
      "y": 12,
      "z": 3,
      "name": "Prototype_Rock_Concrete_Brick"
    },
    {
      "x": -15,
      "y": 13,
      "z": 3,
      "name": "Prototype_Rock_Concrete_Brick"
    },
    {
      "x": -15,
      "y": 6,
      "z": 4,
      "name": "Prototype_Rock_Concrete_Brick"
    },
    {
      "x": -15,
      "y": 7,
      "z": 4,
      "name": "Prototype_Rock_Concrete_Brick"
    },
    {
      "x": -15,
      "y": 12,
      "z": 4,
      "name": "Prototype_Rock_Concrete_Brick"
    },
    {
      "x": -15,
      "y": 13,
      "z": 4,
      "name": "Prototype_Rock_Concrete_Brick"
    },
    {
      "x": -15,
      "y": 6,
      "z": 5,
      "name": "Prototype_Rock_Concrete_Brick"
    },
    {
      "x": -15,
      "y": 7,
      "z": 5,
      "name": "Prototype_Rock_Concrete_Brick"
    },
    {
      "x": -15,
      "y": 12,
      "z": 5,
      "name": "Prototype_Rock_Concrete_Brick"
    },
    {
      "x": -15,
      "y": 13,
      "z": 5,
      "name": "Prototype_Rock_Concrete_Brick"
    },
    {
      "x": -15,
      "y": 14,
      "z": 5,
      "name": "Prototype_Rock_Concrete_Brick"
    },
    {
      "x": -15,
      "y": 6,
      "z": 6,
      "name": "Prototype_Rock_Concrete_Brick"
    },
    {
      "x": -15,
      "y": 7,
      "z": 6,
      "name": "Prototype_Rock_Concrete_Brick"
    },
    {
      "x": -15,
      "y": 12,
      "z": 6,
      "name": "Prototype_Rock_Concrete_Brick"
    },
    {
      "x": -15,
      "y": 13,
      "z": 6,
      "name": "Prototype_Rock_Concrete_Brick"
    },
    {
      "x": -15,
      "y": 14,
      "z": 6,
      "name": "Prototype_Rock_Concrete_Brick"
    },
    {
      "x": -15,
      "y": 6,
      "z": 7,
      "name": "Prototype_Rock_Concrete_Brick"
    },
    {
      "x": -15,
      "y": 7,
      "z": 7,
      "name": "Prototype_Rock_Concrete_Brick"
    },
    {
      "x": -15,
      "y": 12,
      "z": 7,
      "name": "Prototype_Rock_Concrete_Brick"
    },
    {
      "x": -15,
      "y": 13,
      "z": 7,
      "name": "Prototype_Rock_Concrete_Brick"
    },
    {
      "x": -15,
      "y": 14,
      "z": 7,
      "name": "Prototype_Rock_Concrete_Brick"
    },
    {
      "x": -15,
      "y": 6,
      "z": 8,
      "name": "Prototype_Rock_Concrete_Brick"
    },
    {
      "x": -15,
      "y": 7,
      "z": 8,
      "name": "Prototype_Rock_Concrete_Brick"
    },
    {
      "x": -15,
      "y": 12,
      "z": 8,
      "name": "Prototype_Rock_Concrete_Brick"
    },
    {
      "x": -15,
      "y": 13,
      "z": 8,
      "name": "Prototype_Rock_Concrete_Brick"
    },
    {
      "x": -15,
      "y": 14,
      "z": 8,
      "name": "Prototype_Rock_Concrete_Brick"
    },
    {
      "x": -15,
      "y": 6,
      "z": 9,
      "name": "Prototype_Rock_Concrete_Brick"
    },
    {
      "x": -15,
      "y": 7,
      "z": 9,
      "name": "Prototype_Rock_Concrete_Brick"
    },
    {
      "x": -15,
      "y": 12,
      "z": 9,
      "name": "Prototype_Rock_Concrete_Brick"
    },
    {
      "x": -15,
      "y": 13,
      "z": 9,
      "name": "Prototype_Rock_Concrete_Brick"
    },
    {
      "x": -15,
      "y": 14,
      "z": 9,
      "name": "Prototype_Rock_Concrete_Brick"
    },
    {
      "x": -15,
      "y": 6,
      "z": 10,
      "name": "Prototype_Rock_Concrete_Brick"
    },
    {
      "x": -15,
      "y": 7,
      "z": 10,
      "name": "Prototype_Rock_Concrete_Brick"
    },
    {
      "x": -15,
      "y": 12,
      "z": 10,
      "name": "Prototype_Rock_Concrete_Brick"
    },
    {
      "x": -15,
      "y": 13,
      "z": 10,
      "name": "Prototype_Rock_Concrete_Brick"
    },
    {
      "x": -15,
      "y": 6,
      "z": 11,
      "name": "Prototype_Rock_Concrete_Brick"
    },
    {
      "x": -15,
      "y": 7,
      "z": 11,
      "name": "Prototype_Rock_Concrete_Brick"
    },
    {
      "x": -15,
      "y": 12,
      "z": 11,
      "name": "Prototype_Rock_Concrete_Brick"
    },
    {
      "x": -15,
      "y": 13,
      "z": 11,
      "name": "Prototype_Rock_Concrete_Brick"
    },
    {
      "x": -15,
      "y": 6,
      "z": 12,
      "name": "Prototype_Rock_Concrete_Brick"
    },
    {
      "x": -15,
      "y": 7,
      "z": 12,
      "name": "Prototype_Rock_Concrete_Brick"
    },
    {
      "x": -15,
      "y": 12,
      "z": 12,
      "name": "Prototype_Rock_Concrete_Brick"
    },
    {
      "x": -15,
      "y": 13,
      "z": 12,
      "name": "Prototype_Rock_Concrete_Brick"
    },
    {
      "x": -15,
      "y": 6,
      "z": 13,
      "name": "Prototype_Rock_Concrete_Brick"
    },
    {
      "x": -15,
      "y": 7,
      "z": 13,
      "name": "Prototype_Rock_Concrete_Brick"
    },
    {
      "x": -15,
      "y": 12,
      "z": 13,
      "name": "Prototype_Rock_Concrete_Brick"
    },
    {
      "x": -15,
      "y": 13,
      "z": 13,
      "name": "Prototype_Rock_Concrete_Brick"
    },
    {
      "x": -15,
      "y": 6,
      "z": 14,
      "name": "Prototype_Rock_Concrete_Brick"
    },
    {
      "x": -15,
      "y": 7,
      "z": 14,
      "name": "Prototype_Rock_Concrete_Brick"
    },
    {
      "x": -14,
      "y": 7,
      "z": 0,
      "name": "Prototype_Rock_Concrete_Brick"
    },
    {
      "x": -14,
      "y": 8,
      "z": 0,
      "name": "Prototype_Rock_Concrete_Brick"
    },
    {
      "x": -14,
      "y": 12,
      "z": 0,
      "name": "Prototype_Rock_Concrete_Brick"
    },
    {
      "x": -14,
      "y": 13,
      "z": 0,
      "name": "Prototype_Rock_Concrete_Brick"
    },
    {
      "x": -14,
      "y": 6,
      "z": 1,
      "name": "Prototype_Rock_Concrete_Brick"
    },
    {
      "x": -14,
      "y": 7,
      "z": 1,
      "name": "Prototype_Rock_Concrete_Brick"
    },
    {
      "x": -14,
      "y": 8,
      "z": 1,
      "name": "Prototype_Rock_Concrete_Brick"
    },
    {
      "x": -14,
      "y": 12,
      "z": 1,
      "name": "Prototype_Rock_Concrete_Brick"
    },
    {
      "x": -14,
      "y": 13,
      "z": 1,
      "name": "Prototype_Rock_Concrete_Brick"
    },
    {
      "x": -14,
      "y": 6,
      "z": 2,
      "name": "Prototype_Rock_Concrete_Brick"
    },
    {
      "x": -14,
      "y": 7,
      "z": 2,
      "name": "Prototype_Rock_Concrete_Brick"
    },
    {
      "x": -14,
      "y": 8,
      "z": 2,
      "name": "Prototype_Rock_Concrete_Brick"
    },
    {
      "x": -14,
      "y": 12,
      "z": 2,
      "name": "Prototype_Rock_Concrete_Brick"
    },
    {
      "x": -14,
      "y": 13,
      "z": 2,
      "name": "Prototype_Rock_Concrete_Brick"
    },
    {
      "x": -14,
      "y": 6,
      "z": 3,
      "name": "Prototype_Rock_Concrete_Brick"
    },
    {
      "x": -14,
      "y": 7,
      "z": 3,
      "name": "Prototype_Rock_Concrete_Brick"
    },
    {
      "x": -14,
      "y": 8,
      "z": 3,
      "name": "Prototype_Rock_Concrete_Brick"
    },
    {
      "x": -14,
      "y": 11,
      "z": 3,
      "name": "Prototype_Rock_Concrete_Brick"
    },
    {
      "x": -14,
      "y": 12,
      "z": 3,
      "name": "Prototype_Rock_Concrete_Brick"
    },
    {
      "x": -14,
      "y": 13,
      "z": 3,
      "name": "Prototype_Rock_Concrete_Brick"
    },
    {
      "x": -14,
      "y": 6,
      "z": 4,
      "name": "Prototype_Rock_Concrete_Brick"
    },
    {
      "x": -14,
      "y": 7,
      "z": 4,
      "name": "Prototype_Rock_Concrete_Brick"
    },
    {
      "x": -14,
      "y": 8,
      "z": 4,
      "name": "Prototype_Rock_Concrete_Brick"
    },
    {
      "x": -14,
      "y": 11,
      "z": 4,
      "name": "Prototype_Rock_Concrete_Brick"
    },
    {
      "x": -14,
      "y": 12,
      "z": 4,
      "name": "Prototype_Rock_Concrete_Brick"
    },
    {
      "x": -14,
      "y": 13,
      "z": 4,
      "name": "Prototype_Rock_Concrete_Brick"
    },
    {
      "x": -14,
      "y": 6,
      "z": 5,
      "name": "Prototype_Rock_Concrete_Brick"
    },
    {
      "x": -14,
      "y": 7,
      "z": 5,
      "name": "Prototype_Rock_Concrete_Brick"
    },
    {
      "x": -14,
      "y": 8,
      "z": 5,
      "name": "Prototype_Rock_Concrete_Brick"
    },
    {
      "x": -14,
      "y": 11,
      "z": 5,
      "name": "Prototype_Rock_Concrete_Brick"
    },
    {
      "x": -14,
      "y": 12,
      "z": 5,
      "name": "Prototype_Rock_Concrete_Brick"
    },
    {
      "x": -14,
      "y": 13,
      "z": 5,
      "name": "Prototype_Rock_Concrete_Brick"
    },
    {
      "x": -14,
      "y": 6,
      "z": 6,
      "name": "Prototype_Rock_Concrete_Brick"
    },
    {
      "x": -14,
      "y": 7,
      "z": 6,
      "name": "Prototype_Rock_Concrete_Brick"
    },
    {
      "x": -14,
      "y": 8,
      "z": 6,
      "name": "Prototype_Rock_Concrete_Brick"
    },
    {
      "x": -14,
      "y": 11,
      "z": 6,
      "name": "Prototype_Rock_Concrete_Brick"
    },
    {
      "x": -14,
      "y": 12,
      "z": 6,
      "name": "Prototype_Rock_Concrete_Brick"
    },
    {
      "x": -14,
      "y": 13,
      "z": 6,
      "name": "Prototype_Rock_Concrete_Brick"
    },
    {
      "x": -14,
      "y": 6,
      "z": 7,
      "name": "Prototype_Rock_Concrete_Brick"
    },
    {
      "x": -14,
      "y": 7,
      "z": 7,
      "name": "Prototype_Rock_Concrete_Brick"
    },
    {
      "x": -14,
      "y": 8,
      "z": 7,
      "name": "Prototype_Rock_Concrete_Brick"
    },
    {
      "x": -14,
      "y": 11,
      "z": 7,
      "name": "Prototype_Rock_Concrete_Brick"
    },
    {
      "x": -14,
      "y": 12,
      "z": 7,
      "name": "Prototype_Rock_Concrete_Brick"
    },
    {
      "x": -14,
      "y": 13,
      "z": 7,
      "name": "Prototype_Rock_Concrete_Brick"
    },
    {
      "x": -14,
      "y": 6,
      "z": 8,
      "name": "Prototype_Rock_Concrete_Brick"
    },
    {
      "x": -14,
      "y": 7,
      "z": 8,
      "name": "Prototype_Rock_Concrete_Brick"
    },
    {
      "x": -14,
      "y": 8,
      "z": 8,
      "name": "Prototype_Rock_Concrete_Brick"
    },
    {
      "x": -14,
      "y": 11,
      "z": 8,
      "name": "Prototype_Rock_Concrete_Brick"
    },
    {
      "x": -14,
      "y": 12,
      "z": 8,
      "name": "Prototype_Rock_Concrete_Brick"
    },
    {
      "x": -14,
      "y": 13,
      "z": 8,
      "name": "Prototype_Rock_Concrete_Brick"
    },
    {
      "x": -14,
      "y": 6,
      "z": 9,
      "name": "Prototype_Rock_Concrete_Brick"
    },
    {
      "x": -14,
      "y": 7,
      "z": 9,
      "name": "Prototype_Rock_Concrete_Brick"
    },
    {
      "x": -14,
      "y": 8,
      "z": 9,
      "name": "Prototype_Rock_Concrete_Brick"
    },
    {
      "x": -14,
      "y": 11,
      "z": 9,
      "name": "Prototype_Rock_Concrete_Brick"
    },
    {
      "x": -14,
      "y": 12,
      "z": 9,
      "name": "Prototype_Rock_Concrete_Brick"
    },
    {
      "x": -14,
      "y": 13,
      "z": 9,
      "name": "Prototype_Rock_Concrete_Brick"
    },
    {
      "x": -14,
      "y": 6,
      "z": 10,
      "name": "Prototype_Rock_Concrete_Brick"
    },
    {
      "x": -14,
      "y": 7,
      "z": 10,
      "name": "Prototype_Rock_Concrete_Brick"
    },
    {
      "x": -14,
      "y": 8,
      "z": 10,
      "name": "Prototype_Rock_Concrete_Brick"
    },
    {
      "x": -14,
      "y": 11,
      "z": 10,
      "name": "Prototype_Rock_Concrete_Brick"
    },
    {
      "x": -14,
      "y": 12,
      "z": 10,
      "name": "Prototype_Rock_Concrete_Brick"
    },
    {
      "x": -14,
      "y": 13,
      "z": 10,
      "name": "Prototype_Rock_Concrete_Brick"
    },
    {
      "x": -14,
      "y": 6,
      "z": 11,
      "name": "Prototype_Rock_Concrete_Brick"
    },
    {
      "x": -14,
      "y": 7,
      "z": 11,
      "name": "Prototype_Rock_Concrete_Brick"
    },
    {
      "x": -14,
      "y": 8,
      "z": 11,
      "name": "Prototype_Rock_Concrete_Brick"
    },
    {
      "x": -14,
      "y": 12,
      "z": 11,
      "name": "Prototype_Rock_Concrete_Brick"
    },
    {
      "x": -14,
      "y": 13,
      "z": 11,
      "name": "Prototype_Rock_Concrete_Brick"
    },
    {
      "x": -14,
      "y": 6,
      "z": 12,
      "name": "Prototype_Rock_Concrete_Brick"
    },
    {
      "x": -14,
      "y": 7,
      "z": 12,
      "name": "Prototype_Rock_Concrete_Brick"
    },
    {
      "x": -14,
      "y": 8,
      "z": 12,
      "name": "Prototype_Rock_Concrete_Brick"
    },
    {
      "x": -14,
      "y": 12,
      "z": 12,
      "name": "Prototype_Rock_Concrete_Brick"
    },
    {
      "x": -14,
      "y": 13,
      "z": 12,
      "name": "Prototype_Rock_Concrete_Brick"
    },
    {
      "x": -14,
      "y": 7,
      "z": 13,
      "name": "Prototype_Rock_Concrete_Brick"
    },
    {
      "x": -14,
      "y": 8,
      "z": 13,
      "name": "Prototype_Rock_Concrete_Brick"
    },
    {
      "x": -14,
      "y": 12,
      "z": 13,
      "name": "Prototype_Rock_Concrete_Brick"
    },
    {
      "x": -14,
      "y": 13,
      "z": 13,
      "name": "Prototype_Rock_Concrete_Brick"
    },
    {
      "x": -13,
      "y": 7,
      "z": 0,
      "name": "Prototype_Rock_Concrete_Brick"
    },
    {
      "x": -13,
      "y": 8,
      "z": 0,
      "name": "Prototype_Rock_Concrete_Brick"
    },
    {
      "x": -13,
      "y": 11,
      "z": 0,
      "name": "Prototype_Rock_Concrete_Brick"
    },
    {
      "x": -13,
      "y": 12,
      "z": 0,
      "name": "Prototype_Rock_Concrete_Brick"
    },
    {
      "x": -13,
      "y": 13,
      "z": 0,
      "name": "Prototype_Rock_Concrete_Brick"
    },
    {
      "x": -13,
      "y": 7,
      "z": 1,
      "name": "Prototype_Rock_Concrete_Brick"
    },
    {
      "x": -13,
      "y": 8,
      "z": 1,
      "name": "Prototype_Rock_Concrete_Brick"
    },
    {
      "x": -13,
      "y": 11,
      "z": 1,
      "name": "Prototype_Rock_Concrete_Brick"
    },
    {
      "x": -13,
      "y": 12,
      "z": 1,
      "name": "Prototype_Rock_Concrete_Brick"
    },
    {
      "x": -13,
      "y": 13,
      "z": 1,
      "name": "Prototype_Rock_Concrete_Brick"
    },
    {
      "x": -13,
      "y": 7,
      "z": 2,
      "name": "Prototype_Rock_Concrete_Brick"
    },
    {
      "x": -13,
      "y": 8,
      "z": 2,
      "name": "Prototype_Rock_Concrete_Brick"
    },
    {
      "x": -13,
      "y": 11,
      "z": 2,
      "name": "Prototype_Rock_Concrete_Brick"
    },
    {
      "x": -13,
      "y": 12,
      "z": 2,
      "name": "Prototype_Rock_Concrete_Brick"
    },
    {
      "x": -13,
      "y": 13,
      "z": 2,
      "name": "Prototype_Rock_Concrete_Brick"
    },
    {
      "x": -13,
      "y": 7,
      "z": 3,
      "name": "Prototype_Rock_Concrete_Brick"
    },
    {
      "x": -13,
      "y": 8,
      "z": 3,
      "name": "Prototype_Rock_Concrete_Brick"
    },
    {
      "x": -13,
      "y": 11,
      "z": 3,
      "name": "Prototype_Rock_Concrete_Brick"
    },
    {
      "x": -13,
      "y": 12,
      "z": 3,
      "name": "Prototype_Rock_Concrete_Brick"
    },
    {
      "x": -13,
      "y": 13,
      "z": 3,
      "name": "Prototype_Rock_Concrete_Brick"
    },
    {
      "x": -13,
      "y": 7,
      "z": 4,
      "name": "Prototype_Rock_Concrete_Brick"
    },
    {
      "x": -13,
      "y": 8,
      "z": 4,
      "name": "Prototype_Rock_Concrete_Brick"
    },
    {
      "x": -13,
      "y": 11,
      "z": 4,
      "name": "Prototype_Rock_Concrete_Brick"
    },
    {
      "x": -13,
      "y": 12,
      "z": 4,
      "name": "Prototype_Rock_Concrete_Brick"
    },
    {
      "x": -13,
      "y": 13,
      "z": 4,
      "name": "Prototype_Rock_Concrete_Brick"
    },
    {
      "x": -13,
      "y": 7,
      "z": 5,
      "name": "Prototype_Rock_Concrete_Brick"
    },
    {
      "x": -13,
      "y": 8,
      "z": 5,
      "name": "Prototype_Rock_Concrete_Brick"
    },
    {
      "x": -13,
      "y": 11,
      "z": 5,
      "name": "Prototype_Rock_Concrete_Brick"
    },
    {
      "x": -13,
      "y": 12,
      "z": 5,
      "name": "Prototype_Rock_Concrete_Brick"
    },
    {
      "x": -13,
      "y": 13,
      "z": 5,
      "name": "Prototype_Rock_Concrete_Brick"
    },
    {
      "x": -13,
      "y": 7,
      "z": 6,
      "name": "Prototype_Rock_Concrete_Brick"
    },
    {
      "x": -13,
      "y": 8,
      "z": 6,
      "name": "Prototype_Rock_Concrete_Brick"
    },
    {
      "x": -13,
      "y": 11,
      "z": 6,
      "name": "Prototype_Rock_Concrete_Brick"
    },
    {
      "x": -13,
      "y": 12,
      "z": 6,
      "name": "Prototype_Rock_Concrete_Brick"
    },
    {
      "x": -13,
      "y": 13,
      "z": 6,
      "name": "Prototype_Rock_Concrete_Brick"
    },
    {
      "x": -13,
      "y": 7,
      "z": 7,
      "name": "Prototype_Rock_Concrete_Brick"
    },
    {
      "x": -13,
      "y": 8,
      "z": 7,
      "name": "Prototype_Rock_Concrete_Brick"
    },
    {
      "x": -13,
      "y": 11,
      "z": 7,
      "name": "Prototype_Rock_Concrete_Brick"
    },
    {
      "x": -13,
      "y": 12,
      "z": 7,
      "name": "Prototype_Rock_Concrete_Brick"
    },
    {
      "x": -13,
      "y": 13,
      "z": 7,
      "name": "Prototype_Rock_Concrete_Brick"
    },
    {
      "x": -13,
      "y": 7,
      "z": 8,
      "name": "Prototype_Rock_Concrete_Brick"
    },
    {
      "x": -13,
      "y": 8,
      "z": 8,
      "name": "Prototype_Rock_Concrete_Brick"
    },
    {
      "x": -13,
      "y": 11,
      "z": 8,
      "name": "Prototype_Rock_Concrete_Brick"
    },
    {
      "x": -13,
      "y": 12,
      "z": 8,
      "name": "Prototype_Rock_Concrete_Brick"
    },
    {
      "x": -13,
      "y": 13,
      "z": 8,
      "name": "Prototype_Rock_Concrete_Brick"
    },
    {
      "x": -13,
      "y": 7,
      "z": 9,
      "name": "Prototype_Rock_Concrete_Brick"
    },
    {
      "x": -13,
      "y": 8,
      "z": 9,
      "name": "Prototype_Rock_Concrete_Brick"
    },
    {
      "x": -13,
      "y": 11,
      "z": 9,
      "name": "Prototype_Rock_Concrete_Brick"
    },
    {
      "x": -13,
      "y": 12,
      "z": 9,
      "name": "Prototype_Rock_Concrete_Brick"
    },
    {
      "x": -13,
      "y": 13,
      "z": 9,
      "name": "Prototype_Rock_Concrete_Brick"
    },
    {
      "x": -13,
      "y": 7,
      "z": 10,
      "name": "Prototype_Rock_Concrete_Brick"
    },
    {
      "x": -13,
      "y": 8,
      "z": 10,
      "name": "Prototype_Rock_Concrete_Brick"
    },
    {
      "x": -13,
      "y": 11,
      "z": 10,
      "name": "Prototype_Rock_Concrete_Brick"
    },
    {
      "x": -13,
      "y": 12,
      "z": 10,
      "name": "Prototype_Rock_Concrete_Brick"
    },
    {
      "x": -13,
      "y": 13,
      "z": 10,
      "name": "Prototype_Rock_Concrete_Brick"
    },
    {
      "x": -13,
      "y": 7,
      "z": 11,
      "name": "Prototype_Rock_Concrete_Brick"
    },
    {
      "x": -13,
      "y": 8,
      "z": 11,
      "name": "Prototype_Rock_Concrete_Brick"
    },
    {
      "x": -13,
      "y": 11,
      "z": 11,
      "name": "Prototype_Rock_Concrete_Brick"
    },
    {
      "x": -13,
      "y": 12,
      "z": 11,
      "name": "Prototype_Rock_Concrete_Brick"
    },
    {
      "x": -13,
      "y": 13,
      "z": 11,
      "name": "Prototype_Rock_Concrete_Brick"
    },
    {
      "x": -13,
      "y": 7,
      "z": 12,
      "name": "Prototype_Rock_Concrete_Brick"
    },
    {
      "x": -13,
      "y": 8,
      "z": 12,
      "name": "Prototype_Rock_Concrete_Brick"
    },
    {
      "x": -13,
      "y": 11,
      "z": 12,
      "name": "Prototype_Rock_Concrete_Brick"
    },
    {
      "x": -13,
      "y": 12,
      "z": 12,
      "name": "Prototype_Rock_Concrete_Brick"
    },
    {
      "x": -13,
      "y": 13,
      "z": 12,
      "name": "Prototype_Rock_Concrete_Brick"
    },
    {
      "x": -13,
      "y": 7,
      "z": 13,
      "name": "Prototype_Rock_Concrete_Brick"
    },
    {
      "x": -13,
      "y": 8,
      "z": 13,
      "name": "Prototype_Rock_Concrete_Brick"
    },
    {
      "x": -13,
      "y": 11,
      "z": 13,
      "name": "Prototype_Rock_Concrete_Brick"
    },
    {
      "x": -13,
      "y": 12,
      "z": 13,
      "name": "Prototype_Rock_Concrete_Brick"
    },
    {
      "x": -12,
      "y": 7,
      "z": 0,
      "name": "Prototype_Rock_Concrete_Brick"
    },
    {
      "x": -12,
      "y": 8,
      "z": 0,
      "name": "Prototype_Rock_Concrete_Brick"
    },
    {
      "x": -12,
      "y": 11,
      "z": 0,
      "name": "Prototype_Rock_Concrete_Brick"
    },
    {
      "x": -12,
      "y": 12,
      "z": 0,
      "name": "Prototype_Rock_Concrete_Brick"
    },
    {
      "x": -12,
      "y": 7,
      "z": 1,
      "name": "Prototype_Rock_Concrete_Brick"
    },
    {
      "x": -12,
      "y": 8,
      "z": 1,
      "name": "Prototype_Rock_Concrete_Brick"
    },
    {
      "x": -12,
      "y": 11,
      "z": 1,
      "name": "Prototype_Rock_Concrete_Brick"
    },
    {
      "x": -12,
      "y": 12,
      "z": 1,
      "name": "Prototype_Rock_Concrete_Brick"
    },
    {
      "x": -12,
      "y": 7,
      "z": 2,
      "name": "Prototype_Rock_Concrete_Brick"
    },
    {
      "x": -12,
      "y": 8,
      "z": 2,
      "name": "Prototype_Rock_Concrete_Brick"
    },
    {
      "x": -12,
      "y": 11,
      "z": 2,
      "name": "Prototype_Rock_Concrete_Brick"
    },
    {
      "x": -12,
      "y": 12,
      "z": 2,
      "name": "Prototype_Rock_Concrete_Brick"
    },
    {
      "x": -12,
      "y": 7,
      "z": 3,
      "name": "Prototype_Rock_Concrete_Brick"
    },
    {
      "x": -12,
      "y": 8,
      "z": 3,
      "name": "Prototype_Rock_Concrete_Brick"
    },
    {
      "x": -12,
      "y": 11,
      "z": 3,
      "name": "Prototype_Rock_Concrete_Brick"
    },
    {
      "x": -12,
      "y": 12,
      "z": 3,
      "name": "Prototype_Rock_Concrete_Brick"
    },
    {
      "x": -12,
      "y": 7,
      "z": 4,
      "name": "Prototype_Rock_Concrete_Brick"
    },
    {
      "x": -12,
      "y": 8,
      "z": 4,
      "name": "Prototype_Rock_Concrete_Brick"
    },
    {
      "x": -12,
      "y": 11,
      "z": 4,
      "name": "Prototype_Rock_Concrete_Brick"
    },
    {
      "x": -12,
      "y": 12,
      "z": 4,
      "name": "Prototype_Rock_Concrete_Brick"
    },
    {
      "x": -12,
      "y": 13,
      "z": 4,
      "name": "Prototype_Rock_Concrete_Brick"
    },
    {
      "x": -12,
      "y": 7,
      "z": 5,
      "name": "Prototype_Rock_Concrete_Brick"
    },
    {
      "x": -12,
      "y": 8,
      "z": 5,
      "name": "Prototype_Rock_Concrete_Brick"
    },
    {
      "x": -12,
      "y": 11,
      "z": 5,
      "name": "Prototype_Rock_Concrete_Brick"
    },
    {
      "x": -12,
      "y": 12,
      "z": 5,
      "name": "Prototype_Rock_Concrete_Brick"
    },
    {
      "x": -12,
      "y": 13,
      "z": 5,
      "name": "Prototype_Rock_Concrete_Brick"
    },
    {
      "x": -12,
      "y": 7,
      "z": 6,
      "name": "Prototype_Rock_Concrete_Brick"
    },
    {
      "x": -12,
      "y": 8,
      "z": 6,
      "name": "Prototype_Rock_Concrete_Brick"
    },
    {
      "x": -12,
      "y": 11,
      "z": 6,
      "name": "Prototype_Rock_Concrete_Brick"
    },
    {
      "x": -12,
      "y": 12,
      "z": 6,
      "name": "Prototype_Rock_Concrete_Brick"
    },
    {
      "x": -12,
      "y": 13,
      "z": 6,
      "name": "Prototype_Rock_Concrete_Brick"
    },
    {
      "x": -12,
      "y": 7,
      "z": 7,
      "name": "Prototype_Rock_Concrete_Brick"
    },
    {
      "x": -12,
      "y": 8,
      "z": 7,
      "name": "Prototype_Rock_Concrete_Brick"
    },
    {
      "x": -12,
      "y": 11,
      "z": 7,
      "name": "Prototype_Rock_Concrete_Brick"
    },
    {
      "x": -12,
      "y": 12,
      "z": 7,
      "name": "Prototype_Rock_Concrete_Brick"
    },
    {
      "x": -12,
      "y": 13,
      "z": 7,
      "name": "Prototype_Rock_Concrete_Brick"
    },
    {
      "x": -12,
      "y": 7,
      "z": 8,
      "name": "Prototype_Rock_Concrete_Brick"
    },
    {
      "x": -12,
      "y": 8,
      "z": 8,
      "name": "Prototype_Rock_Concrete_Brick"
    },
    {
      "x": -12,
      "y": 11,
      "z": 8,
      "name": "Prototype_Rock_Concrete_Brick"
    },
    {
      "x": -12,
      "y": 12,
      "z": 8,
      "name": "Prototype_Rock_Concrete_Brick"
    },
    {
      "x": -12,
      "y": 13,
      "z": 8,
      "name": "Prototype_Rock_Concrete_Brick"
    },
    {
      "x": -12,
      "y": 7,
      "z": 9,
      "name": "Prototype_Rock_Concrete_Brick"
    },
    {
      "x": -12,
      "y": 8,
      "z": 9,
      "name": "Prototype_Rock_Concrete_Brick"
    },
    {
      "x": -12,
      "y": 11,
      "z": 9,
      "name": "Prototype_Rock_Concrete_Brick"
    },
    {
      "x": -12,
      "y": 12,
      "z": 9,
      "name": "Prototype_Rock_Concrete_Brick"
    },
    {
      "x": -12,
      "y": 13,
      "z": 9,
      "name": "Prototype_Rock_Concrete_Brick"
    },
    {
      "x": -12,
      "y": 7,
      "z": 10,
      "name": "Prototype_Rock_Concrete_Brick"
    },
    {
      "x": -12,
      "y": 8,
      "z": 10,
      "name": "Prototype_Rock_Concrete_Brick"
    },
    {
      "x": -12,
      "y": 11,
      "z": 10,
      "name": "Prototype_Rock_Concrete_Brick"
    },
    {
      "x": -12,
      "y": 12,
      "z": 10,
      "name": "Prototype_Rock_Concrete_Brick"
    },
    {
      "x": -12,
      "y": 7,
      "z": 11,
      "name": "Prototype_Rock_Concrete_Brick"
    },
    {
      "x": -12,
      "y": 8,
      "z": 11,
      "name": "Prototype_Rock_Concrete_Brick"
    },
    {
      "x": -12,
      "y": 11,
      "z": 11,
      "name": "Prototype_Rock_Concrete_Brick"
    },
    {
      "x": -12,
      "y": 12,
      "z": 11,
      "name": "Prototype_Rock_Concrete_Brick"
    },
    {
      "x": -12,
      "y": 7,
      "z": 12,
      "name": "Prototype_Rock_Concrete_Brick"
    },
    {
      "x": -12,
      "y": 8,
      "z": 12,
      "name": "Prototype_Rock_Concrete_Brick"
    },
    {
      "x": -12,
      "y": 11,
      "z": 12,
      "name": "Prototype_Rock_Concrete_Brick"
    },
    {
      "x": -12,
      "y": 12,
      "z": 12,
      "name": "Prototype_Rock_Concrete_Brick"
    },
    {
      "x": -12,
      "y": 7,
      "z": 13,
      "name": "Prototype_Rock_Concrete_Brick"
    },
    {
      "x": -12,
      "y": 8,
      "z": 13,
      "name": "Prototype_Rock_Concrete_Brick"
    },
    {
      "x": -12,
      "y": 11,
      "z": 13,
      "name": "Prototype_Rock_Concrete_Brick"
    },
    {
      "x": -12,
      "y": 12,
      "z": 13,
      "name": "Prototype_Rock_Concrete_Brick"
    },
    {
      "x": -11,
      "y": 8,
      "z": -1,
      "name": "Prototype_Rock_Concrete_Brick"
    },
    {
      "x": -11,
      "y": 9,
      "z": -1,
      "name": "Prototype_Rock_Concrete_Brick"
    },
    {
      "x": -11,
      "y": 11,
      "z": -1,
      "name": "Prototype_Rock_Concrete_Brick"
    },
    {
      "x": -11,
      "y": 8,
      "z": 0,
      "name": "Prototype_Rock_Concrete_Brick"
    },
    {
      "x": -11,
      "y": 9,
      "z": 0,
      "name": "Prototype_Rock_Concrete_Brick"
    },
    {
      "x": -11,
      "y": 11,
      "z": 0,
      "name": "Prototype_Rock_Concrete_Brick"
    },
    {
      "x": -11,
      "y": 12,
      "z": 0,
      "name": "Prototype_Rock_Concrete_Brick"
    },
    {
      "x": -11,
      "y": 8,
      "z": 1,
      "name": "Prototype_Rock_Concrete_Brick"
    },
    {
      "x": -11,
      "y": 9,
      "z": 1,
      "name": "Prototype_Rock_Concrete_Brick"
    },
    {
      "x": -11,
      "y": 11,
      "z": 1,
      "name": "Prototype_Rock_Concrete_Brick"
    },
    {
      "x": -11,
      "y": 12,
      "z": 1,
      "name": "Prototype_Rock_Concrete_Brick"
    },
    {
      "x": -11,
      "y": 8,
      "z": 2,
      "name": "Prototype_Rock_Concrete_Brick"
    },
    {
      "x": -11,
      "y": 9,
      "z": 2,
      "name": "Prototype_Rock_Concrete_Brick"
    },
    {
      "x": -11,
      "y": 10,
      "z": 2,
      "name": "Prototype_Rock_Concrete_Brick"
    },
    {
      "x": -11,
      "y": 11,
      "z": 2,
      "name": "Prototype_Rock_Concrete_Brick"
    },
    {
      "x": -11,
      "y": 12,
      "z": 2,
      "name": "Prototype_Rock_Concrete_Brick"
    },
    {
      "x": -11,
      "y": 8,
      "z": 3,
      "name": "Prototype_Rock_Concrete_Brick"
    },
    {
      "x": -11,
      "y": 9,
      "z": 3,
      "name": "Prototype_Rock_Concrete_Brick"
    },
    {
      "x": -11,
      "y": 10,
      "z": 3,
      "name": "Prototype_Rock_Concrete_Brick"
    },
    {
      "x": -11,
      "y": 11,
      "z": 3,
      "name": "Prototype_Rock_Concrete_Brick"
    },
    {
      "x": -11,
      "y": 12,
      "z": 3,
      "name": "Prototype_Rock_Concrete_Brick"
    },
    {
      "x": -11,
      "y": 8,
      "z": 4,
      "name": "Prototype_Rock_Concrete_Brick"
    },
    {
      "x": -11,
      "y": 9,
      "z": 4,
      "name": "Prototype_Rock_Concrete_Brick"
    },
    {
      "x": -11,
      "y": 10,
      "z": 4,
      "name": "Prototype_Rock_Concrete_Brick"
    },
    {
      "x": -11,
      "y": 11,
      "z": 4,
      "name": "Prototype_Rock_Concrete_Brick"
    },
    {
      "x": -11,
      "y": 12,
      "z": 4,
      "name": "Prototype_Rock_Concrete_Brick"
    },
    {
      "x": -11,
      "y": 8,
      "z": 5,
      "name": "Prototype_Rock_Concrete_Brick"
    },
    {
      "x": -11,
      "y": 9,
      "z": 5,
      "name": "Prototype_Rock_Concrete_Brick"
    },
    {
      "x": -11,
      "y": 10,
      "z": 5,
      "name": "Prototype_Rock_Concrete_Brick"
    },
    {
      "x": -11,
      "y": 11,
      "z": 5,
      "name": "Prototype_Rock_Concrete_Brick"
    },
    {
      "x": -11,
      "y": 12,
      "z": 5,
      "name": "Prototype_Rock_Concrete_Brick"
    },
    {
      "x": -11,
      "y": 8,
      "z": 6,
      "name": "Prototype_Rock_Concrete_Brick"
    },
    {
      "x": -11,
      "y": 9,
      "z": 6,
      "name": "Prototype_Rock_Concrete_Brick"
    },
    {
      "x": -11,
      "y": 10,
      "z": 6,
      "name": "Prototype_Rock_Concrete_Brick"
    },
    {
      "x": -11,
      "y": 11,
      "z": 6,
      "name": "Prototype_Rock_Concrete_Brick"
    },
    {
      "x": -11,
      "y": 12,
      "z": 6,
      "name": "Prototype_Rock_Concrete_Brick"
    },
    {
      "x": -11,
      "y": 8,
      "z": 7,
      "name": "Prototype_Rock_Concrete_Brick"
    },
    {
      "x": -11,
      "y": 9,
      "z": 7,
      "name": "Prototype_Rock_Concrete_Brick"
    },
    {
      "x": -11,
      "y": 10,
      "z": 7,
      "name": "Prototype_Rock_Concrete_Brick"
    },
    {
      "x": -11,
      "y": 11,
      "z": 7,
      "name": "Prototype_Rock_Concrete_Brick"
    },
    {
      "x": -11,
      "y": 12,
      "z": 7,
      "name": "Prototype_Rock_Concrete_Brick"
    },
    {
      "x": -11,
      "y": 8,
      "z": 8,
      "name": "Prototype_Rock_Concrete_Brick"
    },
    {
      "x": -11,
      "y": 9,
      "z": 8,
      "name": "Prototype_Rock_Concrete_Brick"
    },
    {
      "x": -11,
      "y": 10,
      "z": 8,
      "name": "Prototype_Rock_Concrete_Brick"
    },
    {
      "x": -11,
      "y": 11,
      "z": 8,
      "name": "Prototype_Rock_Concrete_Brick"
    },
    {
      "x": -11,
      "y": 12,
      "z": 8,
      "name": "Prototype_Rock_Concrete_Brick"
    },
    {
      "x": -11,
      "y": 8,
      "z": 9,
      "name": "Prototype_Rock_Concrete_Brick"
    },
    {
      "x": -11,
      "y": 9,
      "z": 9,
      "name": "Prototype_Rock_Concrete_Brick"
    },
    {
      "x": -11,
      "y": 10,
      "z": 9,
      "name": "Prototype_Rock_Concrete_Brick"
    },
    {
      "x": -11,
      "y": 11,
      "z": 9,
      "name": "Prototype_Rock_Concrete_Brick"
    },
    {
      "x": -11,
      "y": 12,
      "z": 9,
      "name": "Prototype_Rock_Concrete_Brick"
    },
    {
      "x": -11,
      "y": 8,
      "z": 10,
      "name": "Prototype_Rock_Concrete_Brick"
    },
    {
      "x": -11,
      "y": 9,
      "z": 10,
      "name": "Prototype_Rock_Concrete_Brick"
    },
    {
      "x": -11,
      "y": 10,
      "z": 10,
      "name": "Prototype_Rock_Concrete_Brick"
    },
    {
      "x": -11,
      "y": 11,
      "z": 10,
      "name": "Prototype_Rock_Concrete_Brick"
    },
    {
      "x": -11,
      "y": 12,
      "z": 10,
      "name": "Prototype_Rock_Concrete_Brick"
    },
    {
      "x": -11,
      "y": 8,
      "z": 11,
      "name": "Prototype_Rock_Concrete_Brick"
    },
    {
      "x": -11,
      "y": 9,
      "z": 11,
      "name": "Prototype_Rock_Concrete_Brick"
    },
    {
      "x": -11,
      "y": 11,
      "z": 11,
      "name": "Prototype_Rock_Concrete_Brick"
    },
    {
      "x": -11,
      "y": 12,
      "z": 11,
      "name": "Prototype_Rock_Concrete_Brick"
    },
    {
      "x": -11,
      "y": 8,
      "z": 12,
      "name": "Prototype_Rock_Concrete_Brick"
    },
    {
      "x": -11,
      "y": 9,
      "z": 12,
      "name": "Prototype_Rock_Concrete_Brick"
    },
    {
      "x": -11,
      "y": 11,
      "z": 12,
      "name": "Prototype_Rock_Concrete_Brick"
    },
    {
      "x": -11,
      "y": 12,
      "z": 12,
      "name": "Prototype_Rock_Concrete_Brick"
    },
    {
      "x": -11,
      "y": 8,
      "z": 13,
      "name": "Prototype_Rock_Concrete_Brick"
    },
    {
      "x": -11,
      "y": 9,
      "z": 13,
      "name": "Prototype_Rock_Concrete_Brick"
    },
    {
      "x": -11,
      "y": 11,
      "z": 13,
      "name": "Prototype_Rock_Concrete_Brick"
    },
    {
      "x": -11,
      "y": 12,
      "z": 13,
      "name": "Prototype_Rock_Concrete_Brick"
    },
    {
      "x": -10,
      "y": 9,
      "z": -1,
      "name": "Prototype_Rock_Concrete_Brick"
    },
    {
      "x": -10,
      "y": 11,
      "z": -1,
      "name": "Prototype_Rock_Concrete_Brick"
    },
    {
      "x": -10,
      "y": 8,
      "z": 0,
      "name": "Prototype_Rock_Concrete_Brick"
    },
    {
      "x": -10,
      "y": 9,
      "z": 0,
      "name": "Prototype_Rock_Concrete_Brick"
    },
    {
      "x": -10,
      "y": 10,
      "z": 0,
      "name": "Prototype_Rock_Concrete_Brick"
    },
    {
      "x": -10,
      "y": 11,
      "z": 0,
      "name": "Prototype_Rock_Concrete_Brick"
    },
    {
      "x": -10,
      "y": 12,
      "z": 0,
      "name": "Prototype_Rock_Concrete_Brick"
    },
    {
      "x": -10,
      "y": 8,
      "z": 1,
      "name": "Prototype_Rock_Concrete_Brick"
    },
    {
      "x": -10,
      "y": 9,
      "z": 1,
      "name": "Prototype_Rock_Concrete_Brick"
    },
    {
      "x": -10,
      "y": 10,
      "z": 1,
      "name": "Prototype_Rock_Concrete_Brick"
    },
    {
      "x": -10,
      "y": 11,
      "z": 1,
      "name": "Prototype_Rock_Concrete_Brick"
    },
    {
      "x": -10,
      "y": 12,
      "z": 1,
      "name": "Prototype_Rock_Concrete_Brick"
    },
    {
      "x": -10,
      "y": 8,
      "z": 2,
      "name": "Prototype_Rock_Concrete_Brick"
    },
    {
      "x": -10,
      "y": 9,
      "z": 2,
      "name": "Prototype_Rock_Concrete_Brick"
    },
    {
      "x": -10,
      "y": 10,
      "z": 2,
      "name": "Prototype_Rock_Concrete_Brick"
    },
    {
      "x": -10,
      "y": 11,
      "z": 2,
      "name": "Prototype_Rock_Concrete_Brick"
    },
    {
      "x": -10,
      "y": 12,
      "z": 2,
      "name": "Prototype_Rock_Concrete_Brick"
    },
    {
      "x": -10,
      "y": 8,
      "z": 3,
      "name": "Prototype_Rock_Concrete_Brick"
    },
    {
      "x": -10,
      "y": 9,
      "z": 3,
      "name": "Prototype_Rock_Concrete_Brick"
    },
    {
      "x": -10,
      "y": 10,
      "z": 3,
      "name": "Prototype_Rock_Concrete_Brick"
    },
    {
      "x": -10,
      "y": 11,
      "z": 3,
      "name": "Prototype_Rock_Concrete_Brick"
    },
    {
      "x": -10,
      "y": 12,
      "z": 3,
